Workbook

Sheet Read Me
A1: MULTIFAMILY ACQUISITION MODEL
A3: Original model. Mechanics mirror standard institutional development/acquisition underwriting
A4: (same equation structure as the Stoa-era model you provided), rebuilt from scratch.
A6: HOW TO USE:
A7: 1. Enter values ONLY in blue-font cells on the Inputs tab. Yellow cells are the key drivers.
A8: 2. All other cells are formulas - do not overwrite.
A9: 3. Check the Checks tab: all cells in column B should read OK.
A10: 4. Forecast runs 11 years so a 10-year hold still has forward NOI for exit pricing.
A11: 5. Sale price convention: forward (next-year) NOI divided by exit cap rate.
A12: 6. Loan is sized to the LESSER of Max LTV and Min DSCR constraint - matches bank sizing.
A13: 7. Waterfall: LP preferred return (cumulative, non-compounding annually) -> LP return of
A14: capital -> GP return of capital -> residual split LP/GP. Set LP% = 100% if the investor
... A17: Assumption provenance and every change vs. the Stoa-era model: see Stoa Benchmarks tab.

Sheet Inputs
A1: ACQUISITION | E1: RENT ROLL (in-place)
A2: Purchase Price | B2: 525000 | E2: # Units | F2: Unit Type | G2: SF | H2: Rent/Month | I2: Rent/SF
A3: Closing Costs (% of Price) | B3: 0.02 | E3: 4 | F3: 3 BR/ 2 BA | G3: 980 | H3: 1075 | I3: =IFERROR(H3/G3,0) -> 1.0969388
A4: Loan Fee (% of Loan) | B4: 0.01 | E4: 1 | F4: 1 BR/ 1 BA | G4: 400 | H4: 750 | I4: =IFERROR(H4/G4,0) -> 1.875
A5: Total Units | B5: =E11 -> 5 | E5: 0 | F5: BR/BA | G5: 0 | H5: 0 | I5: =IFERROR(H5/G5,0) -> 0
A6: Price / Unit | B6: =IFERROR(B2/B5,0) -> 105000 | E6: 0 | F6: BR/BA | G6: 0 | H6: 0 | I6: =IFERROR(H6/G6,0) -> 0
E7: 0 | F7: BR/BA | G7: 0 | H7: 0 | I7: =IFERROR(H7/G7,0) -> 0
A8: INCOME | E8: 0 | F8: BR/BA | G8: 0 | H8: 0 | I8: =IFERROR(H8/G8,0) -> 0
A9: Vacancy % | B9: 0.07 | E9: 0 | F9: BR/BA | G9: 0 | H9: 0 | I9: =IFERROR(H9/G9,0) -> 0
A10: Bad Debt % | B10: 0.005 | E10: 0 | F10: BR/BA | G10: 0 | H10: 0 | I10: =IFERROR(H10/G10,0) -> 0
A11: Concessions % | B11: 0 | E11: =SUM(E3:E10) -> 5 | G11: =IFERROR(SUMPRODUCT(G3:G10,E3:E10)/E11,0) -> 864 | H11: =IFERROR(SUMPRODUCT(H3:H10,E3:E10)/E11,0) -> 1010 | I11: =IFERROR(H11/G11,0) -> 1.1689815
A12: Other Income ($/Unit/Month) | B12: 0
A13: Rent Growth (Annual) | B13: 0.02 | E13: REFINANCE (Refi Year 0 = none)
A14: Other Income Growth (Annual) | B14: 0.02 | E14: Refi Year (0 = none) | F14: 0
E15: Refi Valuation Cap Rate | F15: 0.07
A16: OPERATING EXPENSES ($/Unit/Year) | E16: Refi LTV | F16: 0.75
A17: Payroll (0 for small props - see Benchmarks) | B17: 0 | E17: Refi Min DSCR | F17: 1.25
A18: General & Administrative | B18: 200 | E18: Refi Interest Rate | F18: 0.0675
A19: Marketing | B19: 200 | E19: Refi Amortization (Years) | F19: 25
A20: Repairs & Maintenance | B20: 900 | E20: Refi Cost (% of New Loan) | F20: 0.02
A21: Contract Services | B21: 0
A22: Utilities | B22: 300 | E22: COMPUTED REFI (do not edit)
A23: Other | B23: 100 | E23: Refi Value (NOI / Val Cap) | F23: =IFERROR(IF($F$14=0,0,INDEX('Annual CF'!C25:N25,MATCH($F$14,'Annual CF'!C2:N2,0))/$F$15),0) -> 0
A24: Insurance | B24: 2500 | E24: New Loan Amount | F24: =IFERROR(IF($F$14=0,0,MIN($F$16*$F$23,PV($F$18/12,$F$19*12,-(INDEX('Annual CF'!C25:N25,MATCH($F$14,'Annual CF'!C2:N2,0))/$F$17)/12))),0) -> 0
A25: Property Taxes (Annual $, total) | B25: 6038 | E25: Old Loan Payoff at Refi | F25: =IFERROR(IF($F$14=0,0,INDEX('Annual CF'!C35:N35,MATCH($F$14,'Annual CF'!C2:N2,0))),0) -> 0
A26: Property Management Fee (% of EGR) | B26: 0.1 | E26: Refi Costs | F26: =$F$24*$F$20 -> 0
A27: Asset Management Fee (% of EGR) | B27: 0 | E27: Net Cash-Out at Refi | F27: =$F$24-$F$25-$F$26 -> 0
A28: Capital Expense Reserve ($/Unit/Year) | B28: 400 | E28: New Monthly Payment | F28: =IFERROR(IF($F$14=0,0,PMT($F$18/12,$F$19*12,-$F$24)),0) -> 0
A29: Expense Growth (Annual) | B29: 0.025
E30: VALUE-ADD / RENOVATION (0 units = none)
A31: DEBT | E31: Units to Renovate | F31: 0
A32: Max Loan-To-Value (LTV) | B32: 0.75 | E32: Renovation Cost per Unit | F32: 0
A33: Min DSCR (Lender Constraint) | B33: 1.25 | E33: Rent Premium per Unit / Month | F33: 0
A34: Interest Rate (Fixed) | B34: 0.0675 | E34: Units Renovated per Year | F34: 0
A35: Amortization (Years) | B35: 25 | E35: Downtime Months per Turn | F35: 1
A36: Interest-Only Period (Years) | B36: 0 | E36: Renovation Start Year | F36: 1
E38: Total Renovation Budget | F38: =$F$31*$F$32 -> 0
A39: EXIT | E39: Years to Complete | F39: =IFERROR(ROUNDUP($F$31/$F$34,0),0) -> 0
A40: Hold Period (Years, 1-10) | B40: 5
A41: Exit Cap Rate | B41: 0.04959
...

Sheet Annual CF
A1: ANNUAL CASH FLOW
B2: Year | C2: 0 | D2: 1 | E2: 2 | F2: 3 | G2: 4 | H2: 5 | I2: 6 | J2: 7 | K2: 8 | L2: 9 | M2: 10 | N2: 11
B4: Revenue
B5: Gross Potential Rent | D5: =(SUMPRODUCT(Inputs!$E$3:$E$10,Inputs!$H$3:$H$10)+MIN(Inputs!$F$31,MAX(0,(D$2-Inputs!$F$36+1)*Inputs!$F$34))*Inputs!$F$33)*12*(1+Inputs!$B$13)^(D$2-1) -> 60600 | E5: =(SUMPRODUCT(Inputs!$E$3:$E$10,Inputs!$H$3:$H$10)+MIN(Inputs!$F$31,MAX(0,(E$2-Inputs!$F$36+1)*Inputs!$F$34))*Inputs!$F$33)*12*(1+Inputs!$B$13)^(E$2-1) -> 61812 | F5: =(SUMPRODUCT(Inputs!$E$3:$E$10,Inputs!$H$3:$H$10)+MIN(Inputs!$F$31,MAX(0,(F$2-Inputs!$F$36+1)*Inputs!$F$34))*Inputs!$F$33)*12*(1+Inputs!$B$13)^(F$2-1) -> 63048.24 | G5: =(SUMPRODUCT(Inputs!$E$3:$E$10,Inputs!$H$3:$H$10)+MIN(Inputs!$F$31,MAX(0,(G$2-Inputs!$F$36+1)*Inputs!$F$34))*Inputs!$F$33)*12*(1+Inputs!$B$13)^(G$2-1) -> 64309.205 | H5: =(SUMPRODUCT(Inputs!$E$3:$E$10,Inputs!$H$3:$H$10)+MIN(Inputs!$F$31,MAX(0,(H$2-Inputs!$F$36+1)*Inputs!$F$34))*Inputs!$F$33)*12*(1+Inputs!$B$13)^(H$2-1) -> 65595.389 | I5: =(SUMPRODUCT(Inputs!$E$3:$E$10,Inputs!$H$3:$H$10)+MIN(Inputs!$F$31,MAX(0,(I$2-Inputs!$F$36+1)*Inputs!$F$34))*Inputs!$F$33)*12*(1+Inputs!$B$13)^(I$2-1) -> 66907.297 | J5: =(SUMPRODUCT(Inputs!$E$3:$E$10,Inputs!$H$3:$H$10)+MIN(Inputs!$F$31,MAX(0,(J$2-Inputs!$F$36+1)*Inputs!$F$34))*Inputs!$F$33)*12*(1+Inputs!$B$13)^(J$2-1) -> 68245.443 | K5: =(SUMPRODUCT(Inputs!$E$3:$E$10,Inputs!$H$3:$H$10)+MIN(Inputs!$F$31,MAX(0,(K$2-Inputs!$F$36+1)*Inputs!$F$34))*Inputs!$F$33)*12*(1+Inputs!$B$13)^(K$2-1) -> 69610.351 | ... N5: =(SUMPRODUCT(Inputs!$E$3:$E$10,Inputs!$H$3:$H$10)+MIN(Inputs!$F$31,MAX(0,(N$2-Inputs!$F$36+1)*Inputs!$F$34))*Inputs!$F$33)*12*(1+Inputs!$B$13)^(N$2-1) -> 73871.062
B6: Physical Vacancy + Reno Downtime | D6: =-(D5*Inputs!$B$9+(MIN(Inputs!$F$31,MAX(0,(D$2-Inputs!$F$36+1)*Inputs!$F$34))-MIN(Inputs!$F$31,MAX(0,(D$2-Inputs!$F$36)*Inputs!$F$34)))*Inputs!$F$35*Inputs!$H$11*(1+Inputs!$B$13)^(D$2-1)) -> -4242 | E6: =-(E5*Inputs!$B$9+(MIN(Inputs!$F$31,MAX(0,(E$2-Inputs!$F$36+1)*Inputs!$F$34))-MIN(Inputs!$F$31,MAX(0,(E$2-Inputs!$F$36)*Inputs!$F$34)))*Inputs!$F$35*Inputs!$H$11*(1+Inputs!$B$13)^(E$2-1)) -> -4326.84 | F6: =-(F5*Inputs!$B$9+(MIN(Inputs!$F$31,MAX(0,(F$2-Inputs!$F$36+1)*Inputs!$F$34))-MIN(Inputs!$F$31,MAX(0,(F$2-Inputs!$F$36)*Inputs!$F$34)))*Inputs!$F$35*Inputs!$H$11*(1+Inputs!$B$13)^(F$2-1)) -> -4413.3768 | G6: =-(G5*Inputs!$B$9+(MIN(Inputs!$F$31,MAX(0,(G$2-Inputs!$F$36+1)*Inputs!$F$34))-MIN(Inputs!$F$31,MAX(0,(G$2-Inputs!$F$36)*Inputs!$F$34)))*Inputs!$F$35*Inputs!$H$11*(1+Inputs!$B$13)^(G$2-1)) -> -4501.6443 | H6: =-(H5*Inputs!$B$9+(MIN(Inputs!$F$31,MAX(0,(H$2-Inputs!$F$36+1)*Inputs!$F$34))-MIN(Inputs!$F$31,MAX(0,(H$2-Inputs!$F$36)*Inputs!$F$34)))*Inputs!$F$35*Inputs!$H$11*(1+Inputs!$B$13)^(H$2-1)) -> -4591.6772 | I6: =-(I5*Inputs!$B$9+(MIN(Inputs!$F$31,MAX(0,(I$2-Inputs!$F$36+1)*Inputs!$F$34))-MIN(Inputs!$F$31,MAX(0,(I$2-Inputs!$F$36)*Inputs!$F$34)))*Inputs!$F$35*Inputs!$H$11*(1+Inputs!$B$13)^(I$2-1)) -> -4683.5108 | J6: =-(J5*Inputs!$B$9+(MIN(Inputs!$F$31,MAX(0,(J$2-Inputs!$F$36+1)*Inputs!$F$34))-MIN(Inputs!$F$31,MAX(0,(J$2-Inputs!$F$36)*Inputs!$F$34)))*Inputs!$F$35*Inputs!$H$11*(1+Inputs!$B$13)^(J$2-1)) -> -4777.181 | K6: =-(K5*Inputs!$B$9+(MIN(Inputs!$F$31,MAX(0,(K$2-Inputs!$F$36+1)*Inputs!$F$34))-MIN(Inputs!$F$31,MAX(0,(K$2-Inputs!$F$36)*Inputs!$F$34)))*Inputs!$F$35*Inputs!$H$11*(1+Inputs!$B$13)^(K$2-1)) -> -4872.7246 | ... N6: =-(N5*Inputs!$B$9+(MIN(Inputs!$F$31,MAX(0,(N$2-Inputs!$F$36+1)*Inputs!$F$34))-MIN(Inputs!$F$31,MAX(0,(N$2-Inputs!$F$36)*Inputs!$F$34)))*Inputs!$F$35*Inputs!$H$11*(1+Inputs!$B$13)^(N$2-1)) -> -5170.9743
B7: Bad Debt | D7: =-D5*Inputs!$B$10 -> -303 | E7: =-E5*Inputs!$B$10 -> -309.06 | F7: =-F5*Inputs!$B$10 -> -315.2412 | G7: =-G5*Inputs!$B$10 -> -321.54602 | H7: =-H5*Inputs!$B$10 -> -327.97694 | I7: =-I5*Inputs!$B$10 -> -334.53648 | J7: =-J5*Inputs!$B$10 -> -341.22721 | K7: =-K5*Inputs!$B$10 -> -348.05176 | ... N7: =-N5*Inputs!$B$10 -> -369.35531
B8: Concessions | D8: =-D5*Inputs!$B$11 -> 0 | E8: =-E5*Inputs!$B$11 -> 0 | F8: =-F5*Inputs!$B$11 -> 0 | G8: =-G5*Inputs!$B$11 -> 0 | H8: =-H5*Inputs!$B$11 -> 0 | I8: =-I5*Inputs!$B$11 -> 0 | J8: =-J5*Inputs!$B$11 -> 0 | K8: =-K5*Inputs!$B$11 -> 0 | ... N8: =-N5*Inputs!$B$11 -> 0
B9: Net Rental Income | D9: =SUM(D5:D8) -> 56055 | E9: =SUM(E5:E8) -> 57176.1 | F9: =SUM(F5:F8) -> 58319.622 | G9: =SUM(G5:G8) -> 59486.014 | H9: =SUM(H5:H8) -> 60675.735 | I9: =SUM(I5:I8) -> 61889.249 | J9: =SUM(J5:J8) -> 63127.034 | K9: =SUM(K5:K8) -> 64389.575 | ... N9: =SUM(N5:N8) -> 68330.732
B10: Other Income | D10: =Inputs!$B$5*Inputs!$B$12*12*(1-Inputs!$B$9)*(1+Inputs!$B$14)^(D$2-1) -> 0 | E10: =Inputs!$B$5*Inputs!$B$12*12*(1-Inputs!$B$9)*(1+Inputs!$B$14)^(E$2-1) -> 0 | F10: =Inputs!$B$5*Inputs!$B$12*12*(1-Inputs!$B$9)*(1+Inputs!$B$14)^(F$2-1) -> 0 | G10: =Inputs!$B$5*Inputs!$B$12*12*(1-Inputs!$B$9)*(1+Inputs!$B$14)^(G$2-1) -> 0 | H10: =Inputs!$B$5*Inputs!$B$12*12*(1-Inputs!$B$9)*(1+Inputs!$B$14)^(H$2-1) -> 0 | I10: =Inputs!$B$5*Inputs!$B$12*12*(1-Inputs!$B$9)*(1+Inputs!$B$14)^(I$2-1) -> 0 | J10: =Inputs!$B$5*Inputs!$B$12*12*(1-Inputs!$B$9)*(1+Inputs!$B$14)^(J$2-1) -> 0 | K10: =Inputs!$B$5*Inputs!$B$12*12*(1-Inputs!$B$9)*(1+Inputs!$B$14)^(K$2-1) -> 0 | ... N10: =Inputs!$B$5*Inputs!$B$12*12*(1-Inputs!$B$9)*(1+Inputs!$B$14)^(N$2-1) -> 0
B11: Effective Gross Revenue | D11: =D9+D10 -> 56055 | E11: =E9+E10 -> 57176.1 | F11: =F9+F10 -> 58319.622 | G11: =G9+G10 -> 59486.014 | H11: =H9+H10 -> 60675.735 | I11: =I9+I10 -> 61889.249 | J11: =J9+J10 -> 63127.034 | K11: =K9+K10 -> 64389.575 | ... N11: =N9+N10 -> 68330.732
B13: Expenses
B14: Payroll | D14: =-Inputs!$B$17*Inputs!$B$5*(1+Inputs!$B$29)^(D$2-1) -> 0 | E14: =-Inputs!$B$17*Inputs!$B$5*(1+Inputs!$B$29)^(E$2-1) -> 0 | F14: =-Inputs!$B$17*Inputs!$B$5*(1+Inputs!$B$29)^(F$2-1) -> 0 | G14: =-Inputs!$B$17*Inputs!$B$5*(1+Inputs!$B$29)^(G$2-1) -> 0 | H14: =-Inputs!$B$17*Inputs!$B$5*(1+Inputs!$B$29)^(H$2-1) -> 0 | I14: =-Inputs!$B$17*Inputs!$B$5*(1+Inputs!$B$29)^(I$2-1) -> 0 | J14: =-Inputs!$B$17*Inputs!$B$5*(1+Inputs!$B$29)^(J$2-1) -> 0 | K14: =-Inputs!$B$17*Inputs!$B$5*(1+Inputs!$B$29)^(K$2-1) -> 0 | ... N14: =-Inputs!$B$17*Inputs!$B$5*(1+Inputs!$B$29)^(N$2-1) -> 0
B15: General & Administrative | D15: =-Inputs!$B$18*Inputs!$B$5*(1+Inputs!$B$29)^(D$2-1) -> -1000 | E15: =-Inputs!$B$18*Inputs!$B$5*(1+Inputs!$B$29)^(E$2-1) -> -1025 | F15: =-Inputs!$B$18*Inputs!$B$5*(1+Inputs!$B$29)^(F$2-1) -> -1050.625 | G15: =-Inputs!$B$18*Inputs!$B$5*(1+Inputs!$B$29)^(G$2-1) -> -1076.8906 | H15: =-Inputs!$B$18*Inputs!$B$5*(1+Inputs!$B$29)^(H$2-1) -> -1103.8129 | I15: =-Inputs!$B$18*Inputs!$B$5*(1+Inputs!$B$29)^(I$2-1) -> -1131.4082 | J15: =-Inputs!$B$18*Inputs!$B$5*(1+Inputs!$B$29)^(J$2-1) -> -1159.6934 | K15: =-Inputs!$B$18*Inputs!$B$5*(1+Inputs!$B$29)^(K$2-1) -> -1188.6858 | ... N15: =-Inputs!$B$18*Inputs!$B$5*(1+Inputs!$B$29)^(N$2-1) -> -1280.0845
B16: Marketing | D16: =-Inputs!$B$19*Inputs!$B$5*(1+Inputs!$B$29)^(D$2-1) -> -1000 | E16: =-Inputs!$B$19*Inputs!$B$5*(1+Inputs!$B$29)^(E$2-1) -> -1025 | F16: =-Inputs!$B$19*Inputs!$B$5*(1+Inputs!$B$29)^(F$2-1) -> -1050.625 | G16: =-Inputs!$B$19*Inputs!$B$5*(1+Inputs!$B$29)^(G$2-1) -> -1076.8906 | H16: =-Inputs!$B$19*Inputs!$B$5*(1+Inputs!$B$29)^(H$2-1) -> -1103.8129 | I16: =-Inputs!$B$19*Inputs!$B$5*(1+Inputs!$B$29)^(I$2-1) -> -1131.4082 | J16: =-Inputs!$B$19*Inputs!$B$5*(1+Inputs!$B$29)^(J$2-1) -> -1159.6934 | K16: =-Inputs!$B$19*Inputs!$B$5*(1+Inputs!$B$29)^(K$2-1) -> -1188.6858 | ... N16: =-Inputs!$B$19*Inputs!$B$5*(1+Inputs!$B$29)^(N$2-1) -> -1280.0845
B17: Repairs & Maintenance | D17: =-Inputs!$B$20*Inputs!$B$5*(1+Inputs!$B$29)^(D$2-1) -> -4500 | E17: =-Inputs!$B$20*Inputs!$B$5*(1+Inputs!$B$29)^(E$2-1) -> -4612.5 | F17: =-Inputs!$B$20*Inputs!$B$5*(1+Inputs!$B$29)^(F$2-1) -> -4727.8125 | G17: =-Inputs!$B$20*Inputs!$B$5*(1+Inputs!$B$29)^(G$2-1) -> -4846.0078 | H17: =-Inputs!$B$20*Inputs!$B$5*(1+Inputs!$B$29)^(H$2-1) -> -4967.158 | I17: =-Inputs!$B$20*Inputs!$B$5*(1+Inputs!$B$29)^(I$2-1) -> -5091.337 | J17: =-Inputs!$B$20*Inputs!$B$5*(1+Inputs!$B$29)^(J$2-1) -> -5218.6204 | K17: =-Inputs!$B$20*Inputs!$B$5*(1+Inputs!$B$29)^(K$2-1) -> -5349.0859 | ... N17: =-Inputs!$B$20*Inputs!$B$5*(1+Inputs!$B$29)^(N$2-1) -> -5760.3804
B18: Contract Services | D18: =-Inputs!$B$21*Inputs!$B$5*(1+Inputs!$B$29)^(D$2-1) -> 0 | E18: =-Inputs!$B$21*Inputs!$B$5*(1+Inputs!$B$29)^(E$2-1) -> 0 | F18: =-Inputs!$B$21*Inputs!$B$5*(1+Inputs!$B$29)^(F$2-1) -> 0 | G18: =-Inputs!$B$21*Inputs!$B$5*(1+Inputs!$B$29)^(G$2-1) -> 0 | H18: =-Inputs!$B$21*Inputs!$B$5*(1+Inputs!$B$29)^(H$2-1) -> 0 | I18: =-Inputs!$B$21*Inputs!$B$5*(1+Inputs!$B$29)^(I$2-1) -> 0 | J18: =-Inputs!$B$21*Inputs!$B$5*(1+Inputs!$B$29)^(J$2-1) -> 0 | K18: =-Inputs!$B$21*Inputs!$B$5*(1+Inputs!$B$29)^(K$2-1) -> 0 | ... N18: =-Inputs!$B$21*Inputs!$B$5*(1+Inputs!$B$29)^(N$2-1) -> 0
B19: Utilities | D19: =-Inputs!$B$22*Inputs!$B$5*(1+Inputs!$B$29)^(D$2-1) -> -1500 | E19: =-Inputs!$B$22*Inputs!$B$5*(1+Inputs!$B$29)^(E$2-1) -> -1537.5 | F19: =-Inputs!$B$22*Inputs!$B$5*(1+Inputs!$B$29)^(F$2-1) -> -1575.9375 | G19: =-Inputs!$B$22*Inputs!$B$5*(1+Inputs!$B$29)^(G$2-1) -> -1615.3359 | H19: =-Inputs!$B$22*Inputs!$B$5*(1+Inputs!$B$29)^(H$2-1) -> -1655.7193 | I19: =-Inputs!$B$22*Inputs!$B$5*(1+Inputs!$B$29)^(I$2-1) -> -1697.1123 | J19: =-Inputs!$B$22*Inputs!$B$5*(1+Inputs!$B$29)^(J$2-1) -> -1739.5401 | K19: =-Inputs!$B$22*Inputs!$B$5*(1+Inputs!$B$29)^(K$2-1) -> -1783.0286 | ... N19: =-Inputs!$B$22*Inputs!$B$5*(1+Inputs!$B$29)^(N$2-1) -> -1920.1268
B20: Other | D20: =-Inputs!$B$23*Inputs!$B$5*(1+Inputs!$B$29)^(D$2-1) -> -500 | E20: =-Inputs!$B$23*Inputs!$B$5*(1+Inputs!$B$29)^(E$2-1) -> -512.5 | F20: =-Inputs!$B$23*Inputs!$B$5*(1+Inputs!$B$29)^(F$2-1) -> -525.3125 | G20: =-Inputs!$B$23*Inputs!$B$5*(1+Inputs!$B$29)^(G$2-1) -> -538.44531 | H20: =-Inputs!$B$23*Inputs!$B$5*(1+Inputs!$B$29)^(H$2-1) -> -551.90645 | I20: =-Inputs!$B$23*Inputs!$B$5*(1+Inputs!$B$29)^(I$2-1) -> -565.70411 | J20: =-Inputs!$B$23*Inputs!$B$5*(1+Inputs!$B$29)^(J$2-1) -> -579.84671 | K20: =-Inputs!$B$23*Inputs!$B$5*(1+Inputs!$B$29)^(K$2-1) -> -594.34288 | ... N20: =-Inputs!$B$23*Inputs!$B$5*(1+Inputs!$B$29)^(N$2-1) -> -640.04227
B21: Insurance | D21: =-Inputs!$B$24*Inputs!$B$5*(1+Inputs!$B$29)^(D$2-1) -> -12500 | E21: =-Inputs!$B$24*Inputs!$B$5*(1+Inputs!$B$29)^(E$2-1) -> -12812.5 | F21: =-Inputs!$B$24*Inputs!$B$5*(1+Inputs!$B$29)^(F$2-1) -> -13132.812 | G21: =-Inputs!$B$24*Inputs!$B$5*(1+Inputs!$B$29)^(G$2-1) -> -13461.133 | H21: =-Inputs!$B$24*Inputs!$B$5*(1+Inputs!$B$29)^(H$2-1) -> -13797.661 | I21: =-Inputs!$B$24*Inputs!$B$5*(1+Inputs!$B$29)^(I$2-1) -> -14142.603 | J21: =-Inputs!$B$24*Inputs!$B$5*(1+Inputs!$B$29)^(J$2-1) -> -14496.168 | K21: =-Inputs!$B$24*Inputs!$B$5*(1+Inputs!$B$29)^(K$2-1) -> -14858.572 | ... N21: =-Inputs!$B$24*Inputs!$B$5*(1+Inputs!$B$29)^(N$2-1) -> -16001.057
B22: Property Taxes | D22: =-Inputs!$B$25*(1+Inputs!$B$29)^(D$2-1) -> -6038 | E22: =-Inputs!$B$25*(1+Inputs!$B$29)^(E$2-1) -> -6188.95 | F22: =-Inputs!$B$25*(1+Inputs!$B$29)^(F$2-1) -> -6343.6737 | G22: =-Inputs!$B$25*(1+Inputs!$B$29)^(G$2-1) -> -6502.2656 | H22: =-Inputs!$B$25*(1+Inputs!$B$29)^(H$2-1) -> -6664.8222 | I22: =-Inputs!$B$25*(1+Inputs!$B$29)^(I$2-1) -> -6831.4428 | J22: =-Inputs!$B$25*(1+Inputs!$B$29)^(J$2-1) -> -7002.2289 | K22: =-Inputs!$B$25*(1+Inputs!$B$29)^(K$2-1) -> -7177.2846 | ... N22: =-Inputs!$B$25*(1+Inputs!$B$29)^(N$2-1) -> -7729.1505
B23: Property Management Fee | D23: =-D11*Inputs!$B$26 -> -5605.5 | E23: =-E11*Inputs!$B$26 -> -5717.61 | F23: =-F11*Inputs!$B$26 -> -5831.9622 | G23: =-G11*Inputs!$B$26 -> -5948.6014 | H23: =-H11*Inputs!$B$26 -> -6067.5735 | I23: =-I11*Inputs!$B$26 -> -6188.9249 | J23: =-J11*Inputs!$B$26 -> -6312.7034 | K23: =-K11*Inputs!$B$26 -> -6438.9575 | ... N23: =-N11*Inputs!$B$26 -> -6833.0732
B24: Total Operating Expenses | D24: =SUM(D14:D23) -> -32643.5 | E24: =SUM(E14:E23) -> -33431.56 | F24: =SUM(F14:F23) -> -34238.761 | G24: =SUM(G14:G23) -> -35065.57 | H24: =SUM(H14:H23) -> -35912.466 | I24: =SUM(I14:I23) -> -36779.94 | J24: =SUM(J14:J23) -> -37668.494 | K24: =SUM(K14:K23) -> -38578.643 | ... N24: =SUM(N14:N23) -> -41443.999
B25: Net Operating Income | D25: =D11+D24 -> 23411.5 | E25: =E11+E24 -> 23744.54 | F25: =F11+F24 -> 24080.861 | G25: =G11+G24 -> 24420.444 | H25: =H11+H24 -> 24763.268 | I25: =I11+I24 -> 25109.309 | J25: =J11+J24 -> 25458.54 | K25: =K11+K24 -> 25810.932 | ... N25: =N11+N24 -> 26886.733
B26: Capital Expense Reserve | D26: =-Inputs!$B$5*Inputs!$B$28*(1+Inputs!$B$29)^(D$2-1) -> -2000 | E26: =-Inputs!$B$5*Inputs!$B$28*(1+Inputs!$B$29)^(E$2-1) -> -2050 | F26: =-Inputs!$B$5*Inputs!$B$28*(1+Inputs!$B$29)^(F$2-1) -> -2101.25 | G26: =-Inputs!$B$5*Inputs!$B$28*(1+Inputs!$B$29)^(G$2-1) -> -2153.7812 | H26: =-Inputs!$B$5*Inputs!$B$28*(1+Inputs!$B$29)^(H$2-1) -> -2207.6258 | I26: =-Inputs!$B$5*Inputs!$B$28*(1+Inputs!$B$29)^(I$2-1) -> -2262.8164 | J26: =-Inputs!$B$5*Inputs!$B$28*(1+Inputs!$B$29)^(J$2-1) -> -2319.3868 | K26: =-Inputs!$B$5*Inputs!$B$28*(1+Inputs!$B$29)^(K$2-1) -> -2377.3715 | ... N26: =-Inputs!$B$5*Inputs!$B$28*(1+Inputs!$B$29)^(N$2-1) -> -2560.1691
B27: Asset Management Fee | D27: =-D11*Inputs!$B$27 -> 0 | E27: =-E11*Inputs!$B$27 -> 0 | F27: =-F11*Inputs!$B$27 -> 0 | G27: =-G11*Inputs!$B$27 -> 0 | H27: =-H11*Inputs!$B$27 -> 0 | I27: =-I11*Inputs!$B$27 -> 0 | J27: =-J11*Inputs!$B$27 -> 0 | K27: =-K11*Inputs!$B$27 -> 0 | ... N27: =-N11*Inputs!$B$27 -> 0
B28: Cash Flow Before Debt Service | D28: =D25+D26+D27 -> 21411.5 | E28: =E25+E26+E27 -> 21694.54 | F28: =F25+F26+F27 -> 21979.611 | G28: =G25+G26+G27 -> 22266.663 | H28: =H25+H26+H27 -> 22555.643 | I28: =I25+I26+I27 -> 22846.493 | J28: =J25+J26+J27 -> 23139.153 | K28: =K25+K26+K27 -> 23433.561 | ... N28: =N25+N26+N27 -> 24326.564
B30: Debt Service
B31: Beginning Loan Balance | D31: =IF(D$2=1,Inputs!$B$52,IF(AND(Inputs!$F$14>0,D$2=Inputs!$F$14+1),Inputs!$F$24,C35)) -> 225899.64 | E31: =IF(E$2=1,Inputs!$B$52,IF(AND(Inputs!$F$14>0,E$2=Inputs!$F$14+1),Inputs!$F$24,D35)) -> 222308.93 | F31: =IF(F$2=1,Inputs!$B$52,IF(AND(Inputs!$F$14>0,F$2=Inputs!$F$14+1),Inputs!$F$24,E35)) -> 218468.21 | G31: =IF(G$2=1,Inputs!$B$52,IF(AND(Inputs!$F$14>0,G$2=Inputs!$F$14+1),Inputs!$F$24,F35)) -> 214360.06 | H31: =IF(H$2=1,Inputs!$B$52,IF(AND(Inputs!$F$14>0,H$2=Inputs!$F$14+1),Inputs!$F$24,G35)) -> 209965.87 | I31: =IF(I$2=1,Inputs!$B$52,IF(AND(Inputs!$F$14>0,I$2=Inputs!$F$14+1),Inputs!$F$24,H35)) -> 205265.72 | J31: =IF(J$2=1,Inputs!$B$52,IF(AND(Inputs!$F$14>0,J$2=Inputs!$F$14+1),Inputs!$F$24,I35)) -> 200238.31 | K31: =IF(K$2=1,Inputs!$B$52,IF(AND(Inputs!$F$14>0,K$2=Inputs!$F$14+1),Inputs!$F$24,J35)) -> 194860.85 | ... N31: =IF(N$2=1,Inputs!$B$52,IF(AND(Inputs!$F$14>0,N$2=Inputs!$F$14+1),Inputs!$F$24,M35)) -> 176375.86
B32: Interest Payment | D32: =IF(D$2<=Inputs!$B$36,D31*IF(AND(Inputs!$F$14>0,D$2>Inputs!$F$14),Inputs!$F$18,Inputs!$B$34),12*IF(AND(Inputs!$F$14>0,D$2>Inputs!$F$14),Inputs!$F$28,Inputs!$B$53)-(D31-D35)) -> 15138.488 | E32: =IF(E$2<=Inputs!$B$36,E31*IF(AND(Inputs!$F$14>0,E$2>Inputs!$F$14),Inputs!$F$18,Inputs!$B$34),12*IF(AND(Inputs!$F$14>0,E$2>Inputs!$F$14),Inputs!$F$28,Inputs!$B$53)-(E31-E35)) -> 14888.474 | F32: =IF(F$2<=Inputs!$B$36,F31*IF(AND(Inputs!$F$14>0,F$2>Inputs!$F$14),Inputs!$F$18,Inputs!$B$34),12*IF(AND(Inputs!$F$14>0,F$2>Inputs!$F$14),Inputs!$F$28,Inputs!$B$53)-(F31-F35)) -> 14621.053 | G32: =IF(G$2<=Inputs!$B$36,G31*IF(AND(Inputs!$F$14>0,G$2>Inputs!$F$14),Inputs!$F$18,Inputs!$B$34),12*IF(AND(Inputs!$F$14>0,G$2>Inputs!$F$14),Inputs!$F$28,Inputs!$B$53)-(G31-G35)) -> 14335.011 | H32: =IF(H$2<=Inputs!$B$36,H31*IF(AND(Inputs!$F$14>0,H$2>Inputs!$F$14),Inputs!$F$18,Inputs!$B$34),12*IF(AND(Inputs!$F$14>0,H$2>Inputs!$F$14),Inputs!$F$28,Inputs!$B$53)-(H31-H35)) -> 14029.052 | I32: =IF(I$2<=Inputs!$B$36,I31*IF(AND(Inputs!$F$14>0,I$2>Inputs!$F$14),Inputs!$F$18,Inputs!$B$34),12*IF(AND(Inputs!$F$14>0,I$2>Inputs!$F$14),Inputs!$F$28,Inputs!$B$53)-(I31-I35)) -> 13701.791 | J32: =IF(J$2<=Inputs!$B$36,J31*IF(AND(Inputs!$F$14>0,J$2>Inputs!$F$14),Inputs!$F$18,Inputs!$B$34),12*IF(AND(Inputs!$F$14>0,J$2>Inputs!$F$14),Inputs!$F$28,Inputs!$B$53)-(J31-J35)) -> 13351.743 | K32: =IF(K$2<=Inputs!$B$36,K31*IF(AND(Inputs!$F$14>0,K$2>Inputs!$F$14),Inputs!$F$18,Inputs!$B$34),12*IF(AND(Inputs!$F$14>0,K$2>Inputs!$F$14),Inputs!$F$28,Inputs!$B$53)-(K31-K35)) -> 12977.321 | ... N32: =IF(N$2<=Inputs!$B$36,N31*IF(AND(Inputs!$F$14>0,N$2>Inputs!$F$14),Inputs!$F$18,Inputs!$B$34),12*IF(AND(Inputs!$F$14>0,N$2>Inputs!$F$14),Inputs!$F$28,Inputs!$B$53)-(N31-N35)) -> 11690.249
B33: Principal Payment | D33: =D31-D35 -> 3590.7118 | E33: =E31-E35 -> 3840.7256 | F33: =F31-F35 -> 4108.1474 | G33: =G31-G35 -> 4394.1893 | H33: =H31-H35 -> 4700.1476 | I33: =I31-I35 -> 5027.4092 | J33: =J31-J35 -> 5377.4573 | K33: =K31-K35 -> 5751.8786 | ... N33: =N31-N35 -> 7038.9506
B34: Total Debt Service | D34: =D32+D33 -> 18729.2 | E34: =E32+E33 -> 18729.2 | F34: =F32+F33 -> 18729.2 | G34: =G32+G33 -> 18729.2 | H34: =H32+H33 -> 18729.2 | I34: =I32+I33 -> 18729.2 | J34: =J32+J33 -> 18729.2 | K34: =K32+K33 -> 18729.2 | ... N34: =N32+N33 -> 18729.2
B35: Ending Loan Balance | D35: =IF(D$2<=Inputs!$B$36,D31,MAX(0,FV(IF(AND(Inputs!$F$14>0,D$2>Inputs!$F$14),Inputs!$F$18,Inputs!$B$34)/12,12,IF(AND(Inputs!$F$14>0,D$2>Inputs!$F$14),Inputs!$F$28,Inputs!$B$53),-D31))) -> 222308.93 | E35: =IF(E$2<=Inputs!$B$36,E31,MAX(0,FV(IF(AND(Inputs!$F$14>0,E$2>Inputs!$F$14),Inputs!$F$18,Inputs!$B$34)/12,12,IF(AND(Inputs!$F$14>0,E$2>Inputs!$F$14),Inputs!$F$28,Inputs!$B$53),-E31))) -> 218468.21 | F35: =IF(F$2<=Inputs!$B$36,F31,MAX(0,FV(IF(AND(Inputs!$F$14>0,F$2>Inputs!$F$14),Inputs!$F$18,Inputs!$B$34)/12,12,IF(AND(Inputs!$F$14>0,F$2>Inputs!$F$14),Inputs!$F$28,Inputs!$B$53),-F31))) -> 214360.06 | G35: =IF(G$2<=Inputs!$B$36,G31,MAX(0,FV(IF(AND(Inputs!$F$14>0,G$2>Inputs!$F$14),Inputs!$F$18,Inputs!$B$34)/12,12,IF(AND(Inputs!$F$14>0,G$2>Inputs!$F$14),Inputs!$F$28,Inputs!$B$53),-G31))) -> 209965.87 | H35: =IF(H$2<=Inputs!$B$36,H31,MAX(0,FV(IF(AND(Inputs!$F$14>0,H$2>Inputs!$F$14),Inputs!$F$18,Inputs!$B$34)/12,12,IF(AND(Inputs!$F$14>0,H$2>Inputs!$F$14),Inputs!$F$28,Inputs!$B$53),-H31))) -> 205265.72 | I35: =IF(I$2<=Inputs!$B$36,I31,MAX(0,FV(IF(AND(Inputs!$F$14>0,I$2>Inputs!$F$14),Inputs!$F$18,Inputs!$B$34)/12,12,IF(AND(Inputs!$F$14>0,I$2>Inputs!$F$14),Inputs!$F$28,Inputs!$B$53),-I31))) -> 200238.31 | J35: =IF(J$2<=Inputs!$B$36,J31,MAX(0,FV(IF(AND(Inputs!$F$14>0,J$2>Inputs!$F$14),Inputs!$F$18,Inputs!$B$34)/12,12,IF(AND(Inputs!$F$14>0,J$2>Inputs!$F$14),Inputs!$F$28,Inputs!$B$53),-J31))) -> 194860.85 | K35: =IF(K$2<=Inputs!$B$36,K31,MAX(0,FV(IF(AND(Inputs!$F$14>0,K$2>Inputs!$F$14),Inputs!$F$18,Inputs!$B$34)/12,12,IF(AND(Inputs!$F$14>0,K$2>Inputs!$F$14),Inputs!$F$28,Inputs!$B$53),-K31))) -> 189108.98 | ... N35: =IF(N$2<=Inputs!$B$36,N31,MAX(0,FV(IF(AND(Inputs!$F$14>0,N$2>Inputs!$F$14),Inputs!$F$18,Inputs!$B$34)/12,12,IF(AND(Inputs!$F$14>0,N$2>Inputs!$F$14),Inputs!$F$28,Inputs!$B$53),-N31))) -> 169336.91
B37: Cash Flow After Debt Service | D37: =D28-D34 -> 2682.3 | E37: =E28-E34 -> 2965.34 | F37: =F28-F34 -> 3250.4111 | G37: =G28-G34 -> 3537.463 | H37: =H28-H34 -> 3826.4425 | I37: =I28-I34 -> 4117.2928 | J37: =J28-J34 -> 4409.9535 | K37: =K28-K34 -> 4704.3607 | ... N37: =N28-N34 -> 5597.364
B38: DSCR | D38: =IFERROR(D25/D34,"") -> 1.25 | E38: =IFERROR(E25/E34,"") -> 1.2677819 | F38: =IFERROR(F25/F34,"") -> 1.2857389 | G38: =IFERROR(G25/G34,"") -> 1.3038701 | H38: =IFERROR(H25/H34,"") -> 1.3221744 | I38: =IFERROR(I25/I34,"") -> 1.3406504 | J38: =IFERROR(J25/J34,"") -> 1.3592967 | K38: =IFERROR(K25/K34,"") -> 1.3781118 | ... N38: =IFERROR(N25/N34,"") -> 1.4355516
B39: Cash-on-Cash Return | D39: =IFERROR(D37/Inputs!$B$54,"") -> 0.0086009926 | E39: =IFERROR(E37/Inputs!$B$54,"") -> 0.0095085812 | F39: =IFERROR(F37/Inputs!$B$54,"") -> 0.010422683 | G39: =IFERROR(G37/Inputs!$B$54,"") -> 0.011343136 | H39: =IFERROR(H37/Inputs!$B$54,"") -> 0.01226977 | I39: =IFERROR(I37/Inputs!$B$54,"") -> 0.013202403 | J39: =IFERROR(J37/Inputs!$B$54,"") -> 0.014140841 | K39: =IFERROR(K37/Inputs!$B$54,"") -> 0.015084879 | ... N39: =IFERROR(N37/Inputs!$B$54,"") -> 0.01794836
B40: DSCR (after capex reserve) | D40: =IFERROR((D25+D26)/D34,"") -> 1.1432149 | E40: =IFERROR((E25+E26)/E34,"") -> 1.1583271 | F40: =IFERROR((F25+F26)/F34,"") -> 1.1735478 | G40: =IFERROR((G25+G26)/G34,"") -> 1.1888742 | H40: =IFERROR((H25+H26)/H34,"") -> 1.2043036 | I40: =IFERROR((I25+I26)/I34,"") -> 1.2198328 | J40: =IFERROR((J25+J26)/J34,"") -> 1.2354587 | K40: =IFERROR((K25+K26)/K34,"") -> 1.2511779 | ... N40: =IFERROR((N25+N26)/N34,"") -> 1.2988576
B41: Acquisition & Sale
B42: Purchase Price | C42: =-Inputs!$B$2 -> -525000
B43: Closing Costs | C43: =-Inputs!$B$2*Inputs!$B$3 -> -10500
B44: Loan Fees | C44: =-Inputs!$B$52*Inputs!$B$4 -> -2258.9964
...

Sheet Waterfall
A1: LP / GP DISTRIBUTION WATERFALL (Annual)
B2: LP Capital | C2: =Inputs!$B$55 -> 280673.42
B3: GP Capital | C3: =Inputs!$B$56 -> 31185.935
B5: Year | C5: ='Annual CF'!C2 -> 0 | D5: ='Annual CF'!D2 -> 1 | E5: ='Annual CF'!E2 -> 2 | F5: ='Annual CF'!F2 -> 3 | G5: ='Annual CF'!G2 -> 4 | H5: ='Annual CF'!H2 -> 5 | I5: ='Annual CF'!I2 -> 6 | J5: ='Annual CF'!J2 -> 7 | ... N5: ='Annual CF'!N2 -> 11
B6: Distributable Cash Flow | D6: ='Annual CF'!D51 -> 2682.3 | E6: ='Annual CF'!E51 -> 2965.34 | F6: ='Annual CF'!F51 -> 3250.4111 | G6: ='Annual CF'!G51 -> 3537.463 | H6: ='Annual CF'!H51 -> 289708.73 | I6: ='Annual CF'!I51 -> 0 | J6: ='Annual CF'!J51 -> 0 | K6: ='Annual CF'!K51 -> 0 | ... N6: ='Annual CF'!N51 -> 0
B8: TIER 1: LP Preferred Return
B9: Pref Owed - Beginning | D9: =IF(D$5=1,0,C12) -> 0 | E9: =IF(E$5=1,0,D12) -> 19771.573 | F9: =IF(F$5=1,0,E12) -> 39260.107 | G9: =IF(G$5=1,0,F12) -> 58463.569 | H9: =IF(H$5=1,0,G12) -> 77379.98 | I9: =IF(I$5=1,0,H12) -> 0 | J9: =IF(J$5=1,0,I12) -> 0 | K9: =IF(K$5=1,0,J12) -> 0 | ... N9: =IF(N$5=1,0,M12) -> 0
B10: Pref Accrual | D10: =IF(D$5<=Inputs!$B$40,D15*Inputs!$B$47,0) -> 22453.873 | E10: =IF(E$5<=Inputs!$B$40,E15*Inputs!$B$47,0) -> 22453.873 | F10: =IF(F$5<=Inputs!$B$40,F15*Inputs!$B$47,0) -> 22453.873 | G10: =IF(G$5<=Inputs!$B$40,G15*Inputs!$B$47,0) -> 22453.873 | H10: =IF(H$5<=Inputs!$B$40,H15*Inputs!$B$47,0) -> 22453.873 | I10: =IF(I$5<=Inputs!$B$40,I15*Inputs!$B$47,0) -> 0 | J10: =IF(J$5<=Inputs!$B$40,J15*Inputs!$B$47,0) -> 0 | K10: =IF(K$5<=Inputs!$B$40,K15*Inputs!$B$47,0) -> 0 | ... N10: =IF(N$5<=Inputs!$B$40,N15*Inputs!$B$47,0) -> 0
B11: Pref Paid to LP | D11: =MIN(MAX(D6,0),D9+D10) -> 2682.3 | E11: =MIN(MAX(E6,0),E9+E10) -> 2965.34 | F11: =MIN(MAX(F6,0),F9+F10) -> 3250.4111 | G11: =MIN(MAX(G6,0),G9+G10) -> 3537.463 | H11: =MIN(MAX(H6,0),H9+H10) -> 99833.853 | I11: =MIN(MAX(I6,0),I9+I10) -> 0 | J11: =MIN(MAX(J6,0),J9+J10) -> 0 | K11: =MIN(MAX(K6,0),K9+K10) -> 0 | ... N11: =MIN(MAX(N6,0),N9+N10) -> 0
B12: Pref Owed - Ending | D12: =D9+D10-D11 -> 19771.573 | E12: =E9+E10-E11 -> 39260.107 | F12: =F9+F10-F11 -> 58463.569 | G12: =G9+G10-G11 -> 77379.98 | H12: =H9+H10-H11 -> 0 | I12: =I9+I10-I11 -> 0 | J12: =J9+J10-J11 -> 0 | K12: =K9+K10-K11 -> 0 | ... N12: =N9+N10-N11 -> 0
B14: TIER 2: Return of Capital
B15: LP Unreturned Capital - Beg | D15: =IF(D$5=1,$C$2,C17) -> 280673.42 | E15: =IF(E$5=1,$C$2,D17) -> 280673.42 | F15: =IF(F$5=1,$C$2,E17) -> 280673.42 | G15: =IF(G$5=1,$C$2,F17) -> 280673.42 | H15: =IF(H$5=1,$C$2,G17) -> 280673.42 | I15: =IF(I$5=1,$C$2,H17) -> 90798.537 | J15: =IF(J$5=1,$C$2,I17) -> 90798.537 | K15: =IF(K$5=1,$C$2,J17) -> 90798.537 | ... N15: =IF(N$5=1,$C$2,M17) -> 90798.537
B16: LP Return of Capital | D16: =MIN(MAX(D6-D11,0),D15) -> 0 | E16: =MIN(MAX(E6-E11,0),E15) -> 0 | F16: =MIN(MAX(F6-F11,0),F15) -> 0 | G16: =MIN(MAX(G6-G11,0),G15) -> 0 | H16: =MIN(MAX(H6-H11,0),H15) -> 189874.88 | I16: =MIN(MAX(I6-I11,0),I15) -> 0 | J16: =MIN(MAX(J6-J11,0),J15) -> 0 | K16: =MIN(MAX(K6-K11,0),K15) -> 0 | ... N16: =MIN(MAX(N6-N11,0),N15) -> 0
B17: LP Unreturned Capital - End | D17: =D15-D16 -> 280673.42 | E17: =E15-E16 -> 280673.42 | F17: =F15-F16 -> 280673.42 | G17: =G15-G16 -> 280673.42 | H17: =H15-H16 -> 90798.537 | I17: =I15-I16 -> 90798.537 | J17: =J15-J16 -> 90798.537 | K17: =K15-K16 -> 90798.537 | ... N17: =N15-N16 -> 90798.537
B18: GP Unreturned Capital - Beg | D18: =IF(D$5=1,$C$3,C20) -> 31185.935 | E18: =IF(E$5=1,$C$3,D20) -> 31185.935 | F18: =IF(F$5=1,$C$3,E20) -> 31185.935 | G18: =IF(G$5=1,$C$3,F20) -> 31185.935 | H18: =IF(H$5=1,$C$3,G20) -> 31185.935 | I18: =IF(I$5=1,$C$3,H20) -> 31185.935 | J18: =IF(J$5=1,$C$3,I20) -> 31185.935 | K18: =IF(K$5=1,$C$3,J20) -> 31185.935 | ... N18: =IF(N$5=1,$C$3,M20) -> 31185.935
B19: GP Return of Capital | D19: =MIN(MAX(D6-D11-D16,0),D18) -> 0 | E19: =MIN(MAX(E6-E11-E16,0),E18) -> 0 | F19: =MIN(MAX(F6-F11-F16,0),F18) -> 0 | G19: =MIN(MAX(G6-G11-G16,0),G18) -> 0 | H19: =MIN(MAX(H6-H11-H16,0),H18) -> 0 | I19: =MIN(MAX(I6-I11-I16,0),I18) -> 0 | J19: =MIN(MAX(J6-J11-J16,0),J18) -> 0 | K19: =MIN(MAX(K6-K11-K16,0),K18) -> 0 | ... N19: =MIN(MAX(N6-N11-N16,0),N18) -> 0
B20: GP Unreturned Capital - End | D20: =D18-D19 -> 31185.935 | E20: =E18-E19 -> 31185.935 | F20: =F18-F19 -> 31185.935 | G20: =G18-G19 -> 31185.935 | H20: =H18-H19 -> 31185.935 | I20: =I18-I19 -> 31185.935 | J20: =J18-J19 -> 31185.935 | K20: =K18-K19 -> 31185.935 | ... N20: =N18-N19 -> 31185.935
B22: TIER 3: Residual Split
B23: Residual Cash Flow | D23: =MAX(D6-D11-D16-D19,0) -> 0 | E23: =MAX(E6-E11-E16-E19,0) -> 0 | F23: =MAX(F6-F11-F16-F19,0) -> 0 | G23: =MAX(G6-G11-G16-G19,0) -> 0 | H23: =MAX(H6-H11-H16-H19,0) -> 0 | I23: =MAX(I6-I11-I16-I19,0) -> 0 | J23: =MAX(J6-J11-J16-J19,0) -> 0 | K23: =MAX(K6-K11-K16-K19,0) -> 0 | ... N23: =MAX(N6-N11-N16-N19,0) -> 0
B24: LP Residual Share | D24: =D23*Inputs!$B$48 -> 0 | E24: =E23*Inputs!$B$48 -> 0 | F24: =F23*Inputs!$B$48 -> 0 | G24: =G23*Inputs!$B$48 -> 0 | H24: =H23*Inputs!$B$48 -> 0 | I24: =I23*Inputs!$B$48 -> 0 | J24: =J23*Inputs!$B$48 -> 0 | K24: =K23*Inputs!$B$48 -> 0 | ... N24: =N23*Inputs!$B$48 -> 0
B25: GP Residual Share | D25: =D23*Inputs!$B$49 -> 0 | E25: =E23*Inputs!$B$49 -> 0 | F25: =F23*Inputs!$B$49 -> 0 | G25: =G23*Inputs!$B$49 -> 0 | H25: =H23*Inputs!$B$49 -> 0 | I25: =I23*Inputs!$B$49 -> 0 | J25: =J23*Inputs!$B$49 -> 0 | K25: =K23*Inputs!$B$49 -> 0 | ... N25: =N23*Inputs!$B$49 -> 0
B27: LP Net Cash Flow | C27: =-$C$2 -> -280673.42 | D27: =D11+D16+D24 -> 2682.3 | E27: =E11+E16+E24 -> 2965.34 | F27: =F11+F16+F24 -> 3250.4111 | G27: =G11+G16+G24 -> 3537.463 | H27: =H11+H16+H24 -> 289708.73 | I27: =I11+I16+I24 -> 0 | J27: =J11+J16+J24 -> 0 | K27: =K11+K16+K24 -> 0 | ... N27: =N11+N16+N24 -> 0
B28: GP Net Cash Flow | C28: =-$C$3 -> -31185.935 | D28: =D19+D25 -> 0 | E28: =E19+E25 -> 0 | F28: =F19+F25 -> 0 | G28: =G19+G25 -> 0 | H28: =H19+H25 -> 0 | I28: =I19+I25 -> 0 | J28: =J19+J25 -> 0 | K28: =K19+K25 -> 0 | ... N28: =N19+N25 -> 0
B30: LP IRR | C30: =IFERROR(IRR(C27:N27,0.1),"") -> 0.01515802
B31: LP Equity Multiple | C31: =IFERROR(1+SUM(C27:N27)/$C$2,"") -> 1.0764976
B32: LP Total Profit | C32: =SUM(C27:N27) -> 21470.83
B33: GP IRR | C33: =IFERROR(IRR(C28:N28,0.1),"")
B34: GP Equity Multiple | C34: =IFERROR(1+SUM(C28:N28)/$C$3,"") -> 0
B35: GP Total Profit | C35: =SUM(C28:N28) -> -31185.935

Sheet Sensitivity
A1: EXIT CAP RATE SENSITIVITY (at chosen Hold Period)
A3: Forward NOI at Exit | B3: =INDEX('Annual CF'!C25:N25,MATCH(Inputs!$B$40+1,'Annual CF'!C2:N2,0)) -> 25109.309
A4: Loan Payoff at Exit | B4: =INDEX('Annual CF'!C35:N35,MATCH(Inputs!$B$40,'Annual CF'!C2:N2,0)) -> 205265.72
A5: Cum. CF After Debt Svc (Hold Yrs) | B5: =SUMIFS('Annual CF'!D37:N37,'Annual CF'!D2:N2,"<="&Inputs!$B$40) -> 16261.957
A6: Total Equity | B6: =Inputs!$B$54 -> 311859.35
A8: Exit Cap | B8: Sale Price | C8: Net Sale Proceeds | D8: Total Profit | E8: Equity Multiple
A9: 0.05 | B9: =IFERROR($B$3/A9,0) -> 502186.18 | C9: =B9*(1-Inputs!$B$42)-$B$4 -> 281854.88 | D9: =C9+$B$5-$B$6 -> -13742.519 | E9: =IFERROR((C9+$B$5)/$B$6,0) -> 0.9559336
A10: 0.0525 | B10: =IFERROR($B$3/A10,0) -> 478272.56 | C10: =B10*(1-Inputs!$B$42)-$B$4 -> 258658.66 | D10: =C10+$B$5-$B$6 -> -36938.738 | E10: =IFERROR((C10+$B$5)/$B$6,0) -> 0.88155321
A11: 0.055 | B11: =IFERROR($B$3/A11,0) -> 456532.89 | C11: =B11*(1-Inputs!$B$42)-$B$4 -> 237571.19 | D11: =C11+$B$5-$B$6 -> -58026.21 | E11: =IFERROR((C11+$B$5)/$B$6,0) -> 0.81393468
A12: 0.0575 | B12: =IFERROR($B$3/A12,0) -> 436683.64 | C12: =B12*(1-Inputs!$B$42)-$B$4 -> 218317.41 | D12: =C12+$B$5-$B$6 -> -77279.989 | E12: =IFERROR((C12+$B$5)/$B$6,0) -> 0.75219602
A13: 0.06 | B13: =IFERROR($B$3/A13,0) -> 418488.49 | C13: =B13*(1-Inputs!$B$42)-$B$4 -> 200668.11 | D13: =C13+$B$5-$B$6 -> -94929.286 | E13: =IFERROR((C13+$B$5)/$B$6,0) -> 0.69560225
A14: 0.0625 | B14: =IFERROR($B$3/A14,0) -> 401748.95 | C14: =B14*(1-Inputs!$B$42)-$B$4 -> 184430.76 | D14: =C14+$B$5-$B$6 -> -111166.64 | E14: =IFERROR((C14+$B$5)/$B$6,0) -> 0.64353598
A15: 0.065 | B15: =IFERROR($B$3/A15,0) -> 386297.06 | C15: =B15*(1-Inputs!$B$42)-$B$4 -> 169442.43 | D15: =C15+$B$5-$B$6 -> -126154.97 | E15: =IFERROR((C15+$B$5)/$B$6,0) -> 0.59547481
A16: 0.0675 | B16: =IFERROR($B$3/A16,0) -> 371989.77 | C16: =B16*(1-Inputs!$B$42)-$B$4 -> 155564.35 | D16: =C16+$B$5-$B$6 -> -140033.04 | E16: =IFERROR((C16+$B$5)/$B$6,0) -> 0.55097372
A17: 0.07 | B17: =IFERROR($B$3/A17,0) -> 358704.42 | C17: =B17*(1-Inputs!$B$42)-$B$4 -> 142677.56 | D17: =C17+$B$5-$B$6 -> -152919.83 | E17: =IFERROR((C17+$B$5)/$B$6,0) -> 0.50965129
A18: 0.0725 | B18: =IFERROR($B$3/A18,0) -> 346335.3 | C18: =B18*(1-Inputs!$B$42)-$B$4 -> 130679.52 | D18: =C18+$B$5-$B$6 -> -164917.88 | E18: =IFERROR((C18+$B$5)/$B$6,0) -> 0.47117867
A19: 0.075 | B19: =IFERROR($B$3/A19,0) -> 334790.79 | C19: =B19*(1-Inputs!$B$42)-$B$4 -> 119481.34 | D19: =C19+$B$5-$B$6 -> -176116.05 | E19: =IFERROR((C19+$B$5)/$B$6,0) -> 0.4352709
A20: 0.0775 | B20: =IFERROR($B$3/A20,0) -> 323991.09 | C20: =B20*(1-Inputs!$B$42)-$B$4 -> 109005.63 | D20: =C20+$B$5-$B$6 -> -186591.76 | E20: =IFERROR((C20+$B$5)/$B$6,0) -> 0.40167976
A21: 0.08 | B21: =IFERROR($B$3/A21,0) -> 313866.37 | C21: =B21*(1-Inputs!$B$42)-$B$4 -> 99184.653 | D21: =C21+$B$5-$B$6 -> -196412.74 | E21: =IFERROR((C21+$B$5)/$B$6,0) -> 0.37018806

Sheet Stoa Benchmarks
A1: STOA-ERA MODEL ASSUMPTIONS (exact) AND WHAT THIS MODEL CHANGED
A3: OPERATING EXPENSES ($/Unit/Yr) - from Waters at Hammond & Manhattan budgets
A4: Line Item | B4: Hammond | C4: Manhattan | D4: Average (their formula: =AVERAGE)
A5: Payroll | B5: -1661.03 | C5: -1476.9 | D5: -1568.96
A6: General & Administrative | B6: -476.09 | C6: -400.82 | D6: -438.45
A7: Marketing | B7: -362.42 | C7: -395.13 | D7: -378.78
A8: Repairs & Maintenance | B8: -572.19 | C8: -372.59 | D8: -472.39
A9: Utilities | B9: -641.47 | C9: -742.2 | D9: -691.84
A10: Other | B10: -105.04 | C10: -85.33 | D10: -95.19
A11: Insurance | B11: -1094.69 | C11: -1233.33 | D11: -1164.01
A13: THEIR MODEL SETTINGS (exact)
A14: Vacancy 7% | at Refi 7% | B14: Rent Growth 2%/yr | C14: Expense Growth 1%/yr | D14: Capex Reserve $250/unit/yr
A15: Mgmt Fee 3% of EGR (self-managed at scale) | B15: Asset Mgmt Fee 1% of NRI | C15: Bad Debt/Concessions inside vacancy | D15: Other income itemized (valet trash, late fees, pet rent/fees, admin, carport, termination)
A16: Construction: LTC 75%, WSJ Prime + 0.50% | B16: Loan fee $95,000 flat | C16: Hard cost = $122.23/SF x NRSF + $1,000,000 | D16: Contingency: 10% hard / 2% soft; GC Overhead 5%
A17: GC Profit 4% | Developer Fee 3.5% + 0.5% (taken as in-kind equity) | B17: Impact fees $4,127/unit | C17: Draw curve: normal distribution, SD 6 (hard) / 10 (soft) | D17: Lease-up 14 months; ~20.6 units/month (288 units)
A18: Perm: FHA 223(f) refi at month 33 | B18: Valuation cap 5.5%; LTV 75%; DSCR ~1.185 going-in | C18: 420-month amortization; MIP 0.25% | D18: Perm fee ~2.14% of proceeds
A19: Exit: sell at 6.5% cap on forward NOI | B19: Cost of sale 0.75% | C19: Sell-or-Hold toggle | D19: Waterfall: 8% pref; hurdles 10%/12%; promote 10/20/30; GP/LP splits
A21: CHANGES MADE IN THIS MODEL AND WHY
A22: Insurance: $1,164 -> $2,000/unit default | B22: Louisiana insurance costs escalated sharply post-2022; LA is the 3rd most expensive insurance state. Update per actual quote every deal.
A23: Expense growth: 1% -> 2.5% | B23: 1% was aggressive; recent expense inflation (insurance, labor) runs above rents. Conservative default.
A24: Mgmt fee: 3% -> 8% | B24: Stoa self-managed 300+ unit assets. Third-party management on <50 units typically runs 7-10% of collections.
A25: Cost of sale: 0.75% -> 3% | B25: Stoa sold $30M+ assets off-market. Small multifamily sells with brokerage: 2-5% typical.
A26: Expense levels escalated ~3%/yr from their ~2023 budgets | B26: Payroll 1569->1715, G&A 438->480, Mktg 379->415, R&M 472->515, Util 692->755, Other 95->105. | C26: Note: on very small properties (<10 units) payroll is usually $0 (no on-site staff; covered by mgmt fee). Zero it out when appropriate.
A27: Rate defaults: WSJ Prime = 6.75% (as of Dec 11, 2025) | B27: Bank acquisition debt default 6.75% fixed. Replace with your actual quote.
A28: All other equation structures preserved: forward-NOI exit pricing, DSCR/LTV loan sizing, pref-then-ROC-then-split waterfall, fixed/variable expense logic (Development model), bell-curve draws (Development model).

Sheet Checks
A1: Check | B1: Status
A2: Sources = Uses (Loan + Equity = Price + Closing + Fees + Renovation) | B2: =IF(ABS(Inputs!$B$52+Inputs!$B$54-(Inputs!$B$2+Inputs!$B$2*Inputs!$B$3+Inputs!$B$52*Inputs!$B$4+Inputs!$F$38))<0.01,"OK","ERROR") -> OK
A3: Year 1 DSCR meets lender minimum | B3: =IF('Annual CF'!D38>=Inputs!$B$33-0.005,"OK","CHECK") -> OK
A4: Hold period within 1-10 years | B4: =IF(AND(Inputs!$B$40>=1,Inputs!$B$40<=10),"OK","ERROR") -> OK
A5: Waterfall distributions = project levered CF (yrs 1+) | B5: =IF(ABS(SUM(Waterfall!D27:N27)+SUM(Waterfall!D28:N28)-SUMIFS('Annual CF'!D51:N51,'Annual CF'!D2:N2,">=1"))<1,"OK","ERROR") -> OK
A6: Loan balance non-negative at exit | B6: =IF(INDEX('Annual CF'!C35:N35,MATCH(Inputs!$B$40,'Annual CF'!C2:N2,0))>=0,"OK","ERROR") -> OK
A7: Post-reserve DSCR >= 1.15 (lender view, net of replacement reserves) | B7: =IF('Annual CF'!D40>=1.15,"OK","CHECK") -> CHECK
A8: No balloon at maturity (an interest-only period leaves one) | B8: =IF(Inputs!$B$36=0,"OK","CHECK") -> OK
A9: Exit cap not below going-in cap (compression is an unearned assumption) | B9: =IF(Inputs!$B$41>=Inputs!$B$57-0.0001,"OK","CHECK") -> OK
A10: Refi year (if any) falls inside the hold period | B10: =IF(OR(Inputs!$F$14=0,AND(Inputs!$F$14>=1,Inputs!$F$14<Inputs!$B$40)),"OK","CHECK") -> OK
A11: Refi loan does not exceed the refi valuation | B11: =IF(OR(Inputs!$F$14=0,Inputs!$F$24<=Inputs!$F$23*Inputs!$F$16+1),"OK","CHECK") -> OK
A12: Renovation unit count does not exceed the property | B12: =IF(Inputs!$F$31<=Inputs!$B$5,"OK","ERROR") -> OK
A13: Renovation finishes inside the hold period | B13: =IF(OR(Inputs!$F$31=0,Inputs!$F$36+Inputs!$F$39-1<=Inputs!$B$40),"OK","CHECK") -> OK
