Workbook

Sheet Read Me
A1: MULTIFAMILY DEVELOPMENT MODEL
A3: Original model; equation structure mirrors the Stoa-era development model.
A5: HOW TO USE:
A6: 1. Blue cells = inputs (Inputs, Comps, Construction Budget tabs). Yellow = key drivers.
A7: 2. NO iterative calculation needed. Capitalized construction interest is solved
A8: algebraically (loan = LTC x cost / (1 - LTC x (interest factor + fee%))), then the
A9: monthly ledger accrues ACTUAL interest. The Checks tab compares estimate vs. actual.
A10: 3. Rents pull from the Comps tab (weighted comp averages by unit type, less/plus a
A11: delta adjustment) - same VLOOKUP mechanism as the original. Paste real comps there.
A12: 4. Construction draws follow a normal-distribution (bell curve) schedule - SD inputs
A13: for hard and soft costs, same as the original (SD 6 hard / SD 10 soft).
A14: 5. Timeline: month 1 = land close. Construction runs Start Month -> Start+Duration-1.
... A20: 9. All Checks tab cells should read OK before trusting outputs.

Sheet Comps
A1: RENT COMPS
A2: Paste comp rent rolls below. Include=1 to count a row. Summary (rows 4-6) feeds Inputs rents via VLOOKUP.
D3: Include | E3: # Units | F3: Unit Type | G3: SF | H3: Rent/Month | I3: Rent/SF
E4: SUMMARY BY TYPE | F4: 1 BR/ 1 BA | G4: =IFERROR(SUMPRODUCT(($F$10:$F$80=F4)*($D$10:$D$80)*($E$10:$E$80)*($G$10:$G$80))/SUMPRODUCT(($F$10:$F$80=F4)*($D$10:$D$80)*($E$10:$E$80)),0) -> 780 | H4: =IFERROR(SUMPRODUCT(($F$10:$F$80=F4)*($D$10:$D$80)*($E$10:$E$80)*($H$10:$H$80))/SUMPRODUCT(($F$10:$F$80=F4)*($D$10:$D$80)*($E$10:$E$80)),0) -> 1651.4286 | I4: =IFERROR(H4/G4,0) -> 2.1172161
F5: 2 BR/ 2 BA | G5: =IFERROR(SUMPRODUCT(($F$10:$F$80=F5)*($D$10:$D$80)*($E$10:$E$80)*($G$10:$G$80))/SUMPRODUCT(($F$10:$F$80=F5)*($D$10:$D$80)*($E$10:$E$80)),0) -> 1083.3333 | H5: =IFERROR(SUMPRODUCT(($F$10:$F$80=F5)*($D$10:$D$80)*($E$10:$E$80)*($H$10:$H$80))/SUMPRODUCT(($F$10:$F$80=F5)*($D$10:$D$80)*($E$10:$E$80)),0) -> 1993.3333 | I5: =IFERROR(H5/G5,0) -> 1.84
F6: 3 BR/ 2 BA | G6: =IFERROR(SUMPRODUCT(($F$10:$F$80=F6)*($D$10:$D$80)*($E$10:$E$80)*($G$10:$G$80))/SUMPRODUCT(($F$10:$F$80=F6)*($D$10:$D$80)*($E$10:$E$80)),0) -> 1334.2857 | H6: =IFERROR(SUMPRODUCT(($F$10:$F$80=F6)*($D$10:$D$80)*($E$10:$E$80)*($H$10:$H$80))/SUMPRODUCT(($F$10:$F$80=F6)*($D$10:$D$80)*($E$10:$E$80)),0) -> 2451.4286 | I6: =IFERROR(H6/G6,0) -> 1.8372591
A9: COMP DATA (rows 10-80)
D10: 1 | E10: 40 | F10: 1 BR/ 1 BA | G10: 750 | H10: 1600
D11: 1 | E11: 30 | F11: 1 BR/ 1 BA | G11: 820 | H11: 1720
D12: 1 | E12: 48 | F12: 2 BR/ 2 BA | G12: 1050 | H12: 1950
D13: 1 | E13: 24 | F13: 2 BR/ 2 BA | G13: 1150 | H13: 2080
D14: 1 | E14: 16 | F14: 3 BR/ 2 BA | G14: 1300 | H14: 2400
D15: 1 | E15: 12 | F15: 3 BR/ 2 BA | G15: 1380 | H15: 2520

Sheet Inputs
A1: LAND & TIMING | E1: UNIT MIX (rents pull from Comps tab less Delta)
A2: Land Price | B2: 6750000 | E2: # Units | F2: Unit Type | G2: SF | H2: Rent/Month | I2: Rent/SF | K2: Delta vs Comp
A3: Closing Costs (% of Land) | B3: 0.0075 | E3: 134 | F3: 1 BR/ 1 BA | G3: 764 | H3: =IFERROR(VLOOKUP(F3,Comps!$F$4:$I$6,3,FALSE())*(1-K3),0) -> 1717.4857 | I3: =IFERROR(H3/G3,0) -> 2.248018 | K3: -0.04
A4: Start Date (Land Close = Month 1) | B4: =DATE(2026,8,31) -> 46265 | E4: 121 | F4: 2 BR/ 2 BA | G4: 1040 | H4: =IFERROR(VLOOKUP(F4,Comps!$F$4:$I$6,3,FALSE())*(1-K4),0) -> 2093 | I4: =IFERROR(H4/G4,0) -> 2.0125 | K4: -0.05
A5: Net Rentable SF | B5: =SUMPRODUCT(G3:G8,E3:E8) -> 271710 | E5: 33 | F5: 3 BR/ 2 BA | G5: 1318 | H5: =IFERROR(VLOOKUP(F5,Comps!$F$4:$I$6,3,FALSE())*(1-K5),0) -> 2157.2571 | I5: =IFERROR(H5/G5,0) -> 1.6367657 | K5: 0.12
A6: Total Units | B6: =E9 -> 288 | E6: 0 | F6: BR/BA | G6: 0 | H6: =IFERROR(VLOOKUP(F6,Comps!$F$4:$I$6,3,FALSE())*(1-K6),0) -> 0 | I6: =IFERROR(H6/G6,0) -> 0 | K6: 0
E7: 0 | F7: BR/BA | G7: 0 | H7: =IFERROR(VLOOKUP(F7,Comps!$F$4:$I$6,3,FALSE())*(1-K7),0) -> 0 | I7: =IFERROR(H7/G7,0) -> 0 | K7: 0
A8: Construction Duration (Months) | B8: 20 | E8: 0 | F8: BR/BA | G8: 0 | H8: =IFERROR(VLOOKUP(F8,Comps!$F$4:$I$6,3,FALSE())*(1-K8),0) -> 0 | I8: =IFERROR(H8/G8,0) -> 0 | K8: 0
A9: Construction Start Month | B9: 2 | E9: =SUM(E3:E8) -> 288 | G9: =IFERROR(SUMPRODUCT(G3:G8,E3:E8)/E9,0) -> 943.4375 | H9: =IFERROR(SUMPRODUCT(H3:H8,E3:E8)/E9,0) -> 1925.6443
A10: Lease-Up Start Month | B10: 14
A11: Lease-Up Period (Months) | B11: 14
A12: Lease-Up Pace (Units/Month) | B12: =IFERROR(E9/B11,0) -> 20.571429
A13: Stabilization Month | B13: =B10+ROUNDUP(B6*(1-B16)/B12,0) -> 28
A15: REVENUE
A16: Vacancy (Stabilized) | B16: 0.07
A17: Bad Debt % | B17: 0.005
A18: Other Income ($/Occupied Unit/Month) | B18: 40
A19: Rent Growth (Annual) | B19: 0.02
A21: HARD & SOFT COST DRIVERS
A22: Hard Cost ($/NRSF) | B22: 135
A23: Hard Cost Fixed Adder ($) | B23: 1000000
A24: GC Overhead % | B24: 0.05
A25: Hard Cost Contingency % | B25: 0.1
A26: Soft Cost Contingency % | B26: 0.02
A27: GC Profit % | B27: 0.04
A28: Developer Fee % | B28: 0.035
A29: Impact Fees ($/Unit) | B29: 4127
A30: Hard Cost Draw Curve SD (Months) | B30: 6
A31: Soft Cost Draw Curve SD (Months) | B31: 10
A33: OPERATING EXPENSES
A34: Line Item | B34: $/Unit/Yr | C34: % Fixed | D34: Months Prior to Lease-Up
A35: Payroll | B35: 1715 | C35: 1 | D35: 4
A36: General & Administrative | B36: 480 | C36: 1 | D36: 4
A37: Marketing | B37: 415 | C37: 1 | D37: 4
A38: Repairs & Maintenance | B38: 515 | C38: 0.2 | D38: 3
A39: Contract Services | B39: 0 | C39: 0 | D39: 0
A40: Utilities | B40: 755 | C40: 0.5 | D40: 3
A41: Other | B41: 105 | C41: 0 | D41: 0
A42: Insurance | B42: 2000 | C42: 1 | D42: 4
A43: Property Taxes During Construction (Annual $) | B43: 30000
...

Sheet Construction Budget
A1: CONSTRUCTION BUDGET
D2: Per Unit
B3: HARD COSTS
B4: Base Hard Cost ($/SF x NRSF + Adder) | C4: =Inputs!$B$22*Inputs!$B$5+Inputs!$B$23 -> 37680850 | D4: =IFERROR(C4/Inputs!$B$6,0) -> 130836.28
B5: Hard Cost Contingency | C5: =Inputs!$B$25*C4 -> 3768085 | D5: =IFERROR(C5/Inputs!$B$6,0) -> 13083.628
B6: Contractor's Overhead (grossed up) | C6: =(C4+C5)/(1-Inputs!$B$24)-(C4+C5) -> 2181522.9 | D6: =IFERROR(C6/Inputs!$B$6,0) -> 7574.7323
B7: Hard Cost Subtotal | C7: =SUM(C4:C6) -> 43630458 | D7: =IFERROR(C7/Inputs!$B$6,0) -> 151494.65
B9: SOFT COSTS
B10: Architectural | C10: =1800*Inputs!$B$6 -> 518400 | D10: =IFERROR(C10/Inputs!$B$6,0) -> 1800
B11: Landscape Architecture | C11: =150*Inputs!$B$6 -> 43200 | D11: =IFERROR(C11/Inputs!$B$6,0) -> 150
B12: Geotech / Civil / Phase 1 / Title / Legal / Appraisal / Closing | C12: =20000+95000+2500+68000+5100+4500+700 -> 195800 | D12: =IFERROR(C12/Inputs!$B$6,0) -> 679.86111
B13: Builders Risk + General Liability Insurance | C13: =C7/1000*11 -> 479935.04 | D13: =IFERROR(C13/Inputs!$B$6,0) -> 1666.4411
B14: Local Impact Fees | C14: =Inputs!$B$29*Inputs!$B$6 -> 1188576 | D14: =IFERROR(C14/Inputs!$B$6,0) -> 4127
B15: NGBS Green Certification + Consulting | C15: =(230+200)*Inputs!$B$6 -> 123840 | D15: =IFERROR(C15/Inputs!$B$6,0) -> 430
B16: 0.5% Developer Fee (on hard+soft base) | C16: =0.005*(C7+SUM(C10:C15)) -> 230901.04 | D16: =IFERROR(C16/Inputs!$B$6,0) -> 801.73974
B17: Soft Cost Subtotal | C17: =SUM(C10:C16) -> 2780652.1 | D17: =IFERROR(C17/Inputs!$B$6,0) -> 9655.0419
B18: Soft Cost Contingency | C18: =Inputs!$B$26*C17 -> 55613.042 | D18: =IFERROR(C18/Inputs!$B$6,0) -> 193.10084
B19: GC Profit | C19: =Inputs!$B$27*C7 -> 1745218.3 | D19: =IFERROR(C19/Inputs!$B$6,0) -> 6059.7858
B20: Developer Fee | C20: =Inputs!$B$28*(C7+C17+C18+C19) -> 1687417.9 | D20: =IFERROR(C20/Inputs!$B$6,0) -> 5859.0901
B22: TOTAL CONSTRUCTION BUDGET (excl land, interest, loan fee) | C22: =C7+C17+C18+C19+C20 -> 49899359 | D22: =IFERROR(C22/Inputs!$B$6,0) -> 173261.66
B24: Month-1 Items (title/legal/appraisal/closing/phase1/geotech-civil deposits) | C24: =C12 -> 195800
B26: DRAW SCHEDULE (bell curve)
B27: Month | F27: 1 | G27: 2 | H27: 3 | I27: 4 | J27: 5 | K27: 6 | L27: 7 | M27: 8 | N27: 9 | O27: 10 | P27: 11 | Q27: 12 | R27: 13 | S27: 14 | T27: 15 | U27: 16 | V27: 17 | W27: 18 | X27: 19 | Y27: 20 | Z27: 21 | AA27: 22 | AB27: 23 | AC27: 24 | AD27: 25 | AE27: 26 | AF27: 27 | AG27: 28 | AH27: 29 | AI27: 30 | AJ27: 31 | AK27: 32 | AL27: 33 | AM27: 34 | AN27: 35 | AO27: 36 | AP27: 37 | AQ27: 38 | AR27: 39 | AS27: 40 | AT27: 41 | AU27: 42 | AV27: 43 | AW27: 44 | AX27: 45 | AY27: 46 | AZ27: 47 | BA27: 48 | BB27: 49 | BC27: 50 | BD27: 51 | BE27: 52 | BF27: 53 | BG27: 54 | BH27: 55 | BI27: 56 | BJ27: 57 | BK27: 58 | BL27: 59 | BM27: 60 | BN27: 61 | BO27: 62 | BP27: 63 | BQ27: 64 | BR27: 65 | BS27: 66 | BT27: 67 | BU27: 68 | BV27: 69 | BW27: 70 | BX27: 71 | BY27: 72 | BZ27: 73 | CA27: 74 | CB27: 75 | CC27: 76 | CD27: 77 | CE27: 78 | CF27: 79 | CG27: 80 | CH27: 81 | CI27: 82 | CJ27: 83 | CK27: 84 | CL27: 85 | CM27: 86 | CN27: 87 | CO27: 88 | CP27: 89 | CQ27: 90 | CR27: 91 | CS27: 92 | CT27: 93 | CU27: 94 | CV27: 95 | CW27: 96
B28: Hard Curve Raw (NORMDIST) | E28: =SUM(F28:CW28) -> 0.90365165 | F28: =IF(AND(F27>=Inputs!$B$9,F27<=Inputs!$B$9+Inputs!$B$8-1),NORMDIST(F27,Inputs!$B$9+Inputs!$B$8/2,Inputs!$B$30,0),0) -> 0 | G28: =IF(AND(G27>=Inputs!$B$9,G27<=Inputs!$B$9+Inputs!$B$8-1),NORMDIST(G27,Inputs!$B$9+Inputs!$B$8/2,Inputs!$B$30,0),0) -> 0.016579523 | H28: =IF(AND(H27>=Inputs!$B$9,H27<=Inputs!$B$9+Inputs!$B$8-1),NORMDIST(H27,Inputs!$B$9+Inputs!$B$8/2,Inputs!$B$30,0),0) -> 0.021586266 | I28: =IF(AND(I27>=Inputs!$B$9,I27<=Inputs!$B$9+Inputs!$B$8-1),NORMDIST(I27,Inputs!$B$9+Inputs!$B$8/2,Inputs!$B$30,0),0) -> 0.027335012 | J28: =IF(AND(J27>=Inputs!$B$9,J27<=Inputs!$B$9+Inputs!$B$8-1),NORMDIST(J27,Inputs!$B$9+Inputs!$B$8/2,Inputs!$B$30,0),0) -> 0.033666448 | K28: =IF(AND(K27>=Inputs!$B$9,K27<=Inputs!$B$9+Inputs!$B$8-1),NORMDIST(K27,Inputs!$B$9+Inputs!$B$8/2,Inputs!$B$30,0),0) -> 0.040328454 | L28: =IF(AND(L27>=Inputs!$B$9,L27<=Inputs!$B$9+Inputs!$B$8-1),NORMDIST(L27,Inputs!$B$9+Inputs!$B$8/2,Inputs!$B$30,0),0) -> 0.046985313 | M28: =IF(AND(M27>=Inputs!$B$9,M27<=Inputs!$B$9+Inputs!$B$8-1),NORMDIST(M27,Inputs!$B$9+Inputs!$B$8/2,Inputs!$B$30,0),0) -> 0.053241334 | ... CW28: =IF(AND(CW27>=Inputs!$B$9,CW27<=Inputs!$B$9+Inputs!$B$8-1),NORMDIST(CW27,Inputs!$B$9+Inputs!$B$8/2,Inputs!$B$30,0),0) -> 0
B29: Hard Spend | F29: =IF($E$28=0,0,('Construction Budget'!$C$7+$C$19)*F28/$E$28) -> 0 | G29: =IF($E$28=0,0,('Construction Budget'!$C$7+$C$19)*G28/$E$28) -> 832518.9 | H29: =IF($E$28=0,0,('Construction Budget'!$C$7+$C$19)*H28/$E$28) -> 1083925.9 | I29: =IF($E$28=0,0,('Construction Budget'!$C$7+$C$19)*I28/$E$28) -> 1372591.6 | J29: =IF($E$28=0,0,('Construction Budget'!$C$7+$C$19)*J28/$E$28) -> 1690516.3 | K29: =IF($E$28=0,0,('Construction Budget'!$C$7+$C$19)*K28/$E$28) -> 2025040.2 | L29: =IF($E$28=0,0,('Construction Budget'!$C$7+$C$19)*L28/$E$28) -> 2359305.5 | M29: =IF($E$28=0,0,('Construction Budget'!$C$7+$C$19)*M28/$E$28) -> 2673443.4 | ... CW29: =IF($E$28=0,0,('Construction Budget'!$C$7+$C$19)*CW28/$E$28) -> 0
B30: Soft Curve Raw (NORMDIST) | E30: =SUM(F30:CW30) -> 0.68228607 | F30: =IF(AND(F27>=Inputs!$B$9,F27<=Inputs!$B$9+Inputs!$B$8-1),NORMDIST(F27,Inputs!$B$9+Inputs!$B$8/2,Inputs!$B$31,0),0) -> 0 | G30: =IF(AND(G27>=Inputs!$B$9,G27<=Inputs!$B$9+Inputs!$B$8-1),NORMDIST(G27,Inputs!$B$9+Inputs!$B$8/2,Inputs!$B$31,0),0) -> 0.024197072 | H30: =IF(AND(H27>=Inputs!$B$9,H27<=Inputs!$B$9+Inputs!$B$8-1),NORMDIST(H27,Inputs!$B$9+Inputs!$B$8/2,Inputs!$B$31,0),0) -> 0.026608525 | I30: =IF(AND(I27>=Inputs!$B$9,I27<=Inputs!$B$9+Inputs!$B$8-1),NORMDIST(I27,Inputs!$B$9+Inputs!$B$8/2,Inputs!$B$31,0),0) -> 0.028969155 | J30: =IF(AND(J27>=Inputs!$B$9,J27<=Inputs!$B$9+Inputs!$B$8-1),NORMDIST(J27,Inputs!$B$9+Inputs!$B$8/2,Inputs!$B$31,0),0) -> 0.031225393 | K30: =IF(AND(K27>=Inputs!$B$9,K27<=Inputs!$B$9+Inputs!$B$8-1),NORMDIST(K27,Inputs!$B$9+Inputs!$B$8/2,Inputs!$B$31,0),0) -> 0.03332246 | L30: =IF(AND(L27>=Inputs!$B$9,L27<=Inputs!$B$9+Inputs!$B$8-1),NORMDIST(L27,Inputs!$B$9+Inputs!$B$8/2,Inputs!$B$31,0),0) -> 0.035206533 | M30: =IF(AND(M27>=Inputs!$B$9,M27<=Inputs!$B$9+Inputs!$B$8-1),NORMDIST(M27,Inputs!$B$9+Inputs!$B$8/2,Inputs!$B$31,0),0) -> 0.036827014 | ... CW30: =IF(AND(CW27>=Inputs!$B$9,CW27<=Inputs!$B$9+Inputs!$B$8-1),NORMDIST(CW27,Inputs!$B$9+Inputs!$B$8/2,Inputs!$B$31,0),0) -> 0
B31: Soft Spend (curve portion) | F31: =IF($E$30=0,0,($C$17+$C$18+$C$20-$C$24)*F30/$E$30) -> 0 | G31: =IF($E$30=0,0,($C$17+$C$18+$C$20-$C$24)*G30/$E$30) -> 153487.08 | H31: =IF($E$30=0,0,($C$17+$C$18+$C$20-$C$24)*H30/$E$30) -> 168783.43 | I31: =IF($E$30=0,0,($C$17+$C$18+$C$20-$C$24)*I30/$E$30) -> 183757.4 | J31: =IF($E$30=0,0,($C$17+$C$18+$C$20-$C$24)*J30/$E$30) -> 198069.19 | K31: =IF($E$30=0,0,($C$17+$C$18+$C$20-$C$24)*K30/$E$30) -> 211371.33 | L31: =IF($E$30=0,0,($C$17+$C$18+$C$20-$C$24)*L30/$E$30) -> 223322.39 | M31: =IF($E$30=0,0,($C$17+$C$18+$C$20-$C$24)*M30/$E$30) -> 233601.44 | ... CW31: =IF($E$30=0,0,($C$17+$C$18+$C$20-$C$24)*CW30/$E$30) -> 0
B32: Month-1 Lump | F32: =IF(F27=1,$C$24,0) -> 195800 | G32: =IF(G27=1,$C$24,0) -> 0 | H32: =IF(H27=1,$C$24,0) -> 0 | I32: =IF(I27=1,$C$24,0) -> 0 | J32: =IF(J27=1,$C$24,0) -> 0 | K32: =IF(K27=1,$C$24,0) -> 0 | L32: =IF(L27=1,$C$24,0) -> 0 | M32: =IF(M27=1,$C$24,0) -> 0 | ... CW32: =IF(CW27=1,$C$24,0) -> 0
B33: Total Construction Spend | F33: =F29+F31+F32 -> 195800 | G33: =G29+G31+G32 -> 986005.98 | H33: =H29+H31+H32 -> 1252709.3 | I33: =I29+I31+I32 -> 1556349 | J33: =J29+J31+J32 -> 1888585.5 | K33: =K29+K31+K32 -> 2236411.5 | L33: =L29+L31+L32 -> 2582627.9 | M33: =M29+M31+M32 -> 2907044.9 | ... CW33: =CW29+CW31+CW32 -> 0
B35: Check: Sum of Draws = Total Budget | C35: =IF(ABS(SUM(F33:CW33)-C22)<1,"OK","ERROR") -> OK

Sheet Monthly CF
B1: Month | C1: 1 | D1: 2 | E1: 3 | F1: 4 | G1: 5 | H1: 6 | I1: 7 | J1: 8 | K1: 9 | L1: 10 | M1: 11 | N1: 12 | O1: 13 | P1: 14 | Q1: 15 | R1: 16 | S1: 17 | T1: 18 | U1: 19 | V1: 20 | W1: 21 | X1: 22 | Y1: 23 | Z1: 24 | AA1: 25 | AB1: 26 | AC1: 27 | AD1: 28 | AE1: 29 | AF1: 30 | AG1: 31 | AH1: 32 | AI1: 33 | AJ1: 34 | AK1: 35 | AL1: 36 | AM1: 37 | AN1: 38 | AO1: 39 | AP1: 40 | AQ1: 41 | AR1: 42 | AS1: 43 | AT1: 44 | AU1: 45 | AV1: 46 | AW1: 47 | AX1: 48 | AY1: 49 | AZ1: 50 | BA1: 51 | BB1: 52 | BC1: 53 | BD1: 54 | BE1: 55 | BF1: 56 | BG1: 57 | BH1: 58 | BI1: 59 | BJ1: 60 | BK1: 61 | BL1: 62 | BM1: 63 | BN1: 64 | BO1: 65 | BP1: 66 | BQ1: 67 | BR1: 68 | BS1: 69 | BT1: 70 | BU1: 71 | BV1: 72 | BW1: 73 | BX1: 74 | BY1: 75 | BZ1: 76 | CA1: 77 | CB1: 78 | CC1: 79 | CD1: 80 | CE1: 81 | CF1: 82 | CG1: 83 | CH1: 84 | CI1: 85 | CJ1: 86 | CK1: 87 | CL1: 88 | CM1: 89 | CN1: 90 | CO1: 91 | CP1: 92 | CQ1: 93 | CR1: 94 | CS1: 95 | CT1: 96
B2: Date | C2: =EDATE(Inputs!$B$4,C1-1) -> 46265 | D2: =EDATE(Inputs!$B$4,D1-1) -> 46295 | E2: =EDATE(Inputs!$B$4,E1-1) -> 46326 | F2: =EDATE(Inputs!$B$4,F1-1) -> 46356 | G2: =EDATE(Inputs!$B$4,G1-1) -> 46387 | H2: =EDATE(Inputs!$B$4,H1-1) -> 46418 | I2: =EDATE(Inputs!$B$4,I1-1) -> 46446 | J2: =EDATE(Inputs!$B$4,J1-1) -> 46477 | ... CT2: =EDATE(Inputs!$B$4,CT1-1) -> 49156
B3: Year Index | C3: =INT((C1-1)/12)+1 -> 1 | D3: =INT((D1-1)/12)+1 -> 1 | E3: =INT((E1-1)/12)+1 -> 1 | F3: =INT((F1-1)/12)+1 -> 1 | G3: =INT((G1-1)/12)+1 -> 1 | H3: =INT((H1-1)/12)+1 -> 1 | I3: =INT((I1-1)/12)+1 -> 1 | J3: =INT((J1-1)/12)+1 -> 1 | ... CT3: =INT((CT1-1)/12)+1 -> 8
B5: Units Leased | C5: =MAX(0,MIN(Inputs!$B$6,(C1-Inputs!$B$10+1)*Inputs!$B$12)) -> 0 | D5: =MAX(0,MIN(Inputs!$B$6,(D1-Inputs!$B$10+1)*Inputs!$B$12)) -> 0 | E5: =MAX(0,MIN(Inputs!$B$6,(E1-Inputs!$B$10+1)*Inputs!$B$12)) -> 0 | F5: =MAX(0,MIN(Inputs!$B$6,(F1-Inputs!$B$10+1)*Inputs!$B$12)) -> 0 | G5: =MAX(0,MIN(Inputs!$B$6,(G1-Inputs!$B$10+1)*Inputs!$B$12)) -> 0 | H5: =MAX(0,MIN(Inputs!$B$6,(H1-Inputs!$B$10+1)*Inputs!$B$12)) -> 0 | I5: =MAX(0,MIN(Inputs!$B$6,(I1-Inputs!$B$10+1)*Inputs!$B$12)) -> 0 | J5: =MAX(0,MIN(Inputs!$B$6,(J1-Inputs!$B$10+1)*Inputs!$B$12)) -> 0 | ... CT5: =MAX(0,MIN(Inputs!$B$6,(CT1-Inputs!$B$10+1)*Inputs!$B$12)) -> 288
B6: Occupied Units | C6: =MIN(C5,Inputs!$B$6*(1-Inputs!$B$16)) -> 0 | D6: =MIN(D5,Inputs!$B$6*(1-Inputs!$B$16)) -> 0 | E6: =MIN(E5,Inputs!$B$6*(1-Inputs!$B$16)) -> 0 | F6: =MIN(F5,Inputs!$B$6*(1-Inputs!$B$16)) -> 0 | G6: =MIN(G5,Inputs!$B$6*(1-Inputs!$B$16)) -> 0 | H6: =MIN(H5,Inputs!$B$6*(1-Inputs!$B$16)) -> 0 | I6: =MIN(I5,Inputs!$B$6*(1-Inputs!$B$16)) -> 0 | J6: =MIN(J5,Inputs!$B$6*(1-Inputs!$B$16)) -> 0 | ... CT6: =MIN(CT5,Inputs!$B$6*(1-Inputs!$B$16)) -> 267.84
B7: Gross Potential Rent | C7: =SUMPRODUCT(Inputs!$E$3:$E$8,Inputs!$H$3:$H$8)*(1+Inputs!$B$19)^(C3-1) -> 554585.57 | D7: =SUMPRODUCT(Inputs!$E$3:$E$8,Inputs!$H$3:$H$8)*(1+Inputs!$B$19)^(D3-1) -> 554585.57 | E7: =SUMPRODUCT(Inputs!$E$3:$E$8,Inputs!$H$3:$H$8)*(1+Inputs!$B$19)^(E3-1) -> 554585.57 | F7: =SUMPRODUCT(Inputs!$E$3:$E$8,Inputs!$H$3:$H$8)*(1+Inputs!$B$19)^(F3-1) -> 554585.57 | G7: =SUMPRODUCT(Inputs!$E$3:$E$8,Inputs!$H$3:$H$8)*(1+Inputs!$B$19)^(G3-1) -> 554585.57 | H7: =SUMPRODUCT(Inputs!$E$3:$E$8,Inputs!$H$3:$H$8)*(1+Inputs!$B$19)^(H3-1) -> 554585.57 | I7: =SUMPRODUCT(Inputs!$E$3:$E$8,Inputs!$H$3:$H$8)*(1+Inputs!$B$19)^(I3-1) -> 554585.57 | J7: =SUMPRODUCT(Inputs!$E$3:$E$8,Inputs!$H$3:$H$8)*(1+Inputs!$B$19)^(J3-1) -> 554585.57 | ... CT7: =SUMPRODUCT(Inputs!$E$3:$E$8,Inputs!$H$3:$H$8)*(1+Inputs!$B$19)^(CT3-1) -> 637044.5
B8: Vacancy / Lease-Up Loss | C8: =-C7*(1-C6/Inputs!$B$6) -> -554585.57 | D8: =-D7*(1-D6/Inputs!$B$6) -> -554585.57 | E8: =-E7*(1-E6/Inputs!$B$6) -> -554585.57 | F8: =-F7*(1-F6/Inputs!$B$6) -> -554585.57 | G8: =-G7*(1-G6/Inputs!$B$6) -> -554585.57 | H8: =-H7*(1-H6/Inputs!$B$6) -> -554585.57 | I8: =-I7*(1-I6/Inputs!$B$6) -> -554585.57 | J8: =-J7*(1-J6/Inputs!$B$6) -> -554585.57 | ... CT8: =-CT7*(1-CT6/Inputs!$B$6) -> -44593.115
B9: Bad Debt | C9: =-(C7+C8)*Inputs!$B$17 -> 0 | D9: =-(D7+D8)*Inputs!$B$17 -> 0 | E9: =-(E7+E8)*Inputs!$B$17 -> 0 | F9: =-(F7+F8)*Inputs!$B$17 -> 0 | G9: =-(G7+G8)*Inputs!$B$17 -> 0 | H9: =-(H7+H8)*Inputs!$B$17 -> 0 | I9: =-(I7+I8)*Inputs!$B$17 -> 0 | J9: =-(J7+J8)*Inputs!$B$17 -> 0 | ... CT9: =-(CT7+CT8)*Inputs!$B$17 -> -2962.2569
B10: Net Rental Income | C10: =SUM(C7:C9) -> 0 | D10: =SUM(D7:D9) -> 0 | E10: =SUM(E7:E9) -> 0 | F10: =SUM(F7:F9) -> 0 | G10: =SUM(G7:G9) -> 0 | H10: =SUM(H7:H9) -> 0 | I10: =SUM(I7:I9) -> 0 | J10: =SUM(J7:J9) -> 0 | ... CT10: =SUM(CT7:CT9) -> 589489.13
B11: Other Income | C11: =C6*Inputs!$B$18*(1+Inputs!$B$19)^(C3-1) -> 0 | D11: =D6*Inputs!$B$18*(1+Inputs!$B$19)^(D3-1) -> 0 | E11: =E6*Inputs!$B$18*(1+Inputs!$B$19)^(E3-1) -> 0 | F11: =F6*Inputs!$B$18*(1+Inputs!$B$19)^(F3-1) -> 0 | G11: =G6*Inputs!$B$18*(1+Inputs!$B$19)^(G3-1) -> 0 | H11: =H6*Inputs!$B$18*(1+Inputs!$B$19)^(H3-1) -> 0 | I11: =I6*Inputs!$B$18*(1+Inputs!$B$19)^(I3-1) -> 0 | J11: =J6*Inputs!$B$18*(1+Inputs!$B$19)^(J3-1) -> 0 | ... CT11: =CT6*Inputs!$B$18*(1+Inputs!$B$19)^(CT3-1) -> 12306.559
B12: Effective Gross Revenue | C12: =C10+C11 -> 0 | D12: =D10+D11 -> 0 | E12: =E10+E11 -> 0 | F12: =F10+F11 -> 0 | G12: =G10+G11 -> 0 | H12: =H10+H11 -> 0 | I12: =I10+I11 -> 0 | J12: =J10+J11 -> 0 | ... CT12: =CT10+CT11 -> 601795.68
B14: Payroll | C14: =IF(C1>=Inputs!$B$10-Inputs!$D$35,-(Inputs!$B$35*Inputs!$B$6/12)*(1+Inputs!$B$48)^(C3-1)*(Inputs!$C$35+(1-Inputs!$C$35)*C6/Inputs!$B$6),0) -> 0 | D14: =IF(D1>=Inputs!$B$10-Inputs!$D$35,-(Inputs!$B$35*Inputs!$B$6/12)*(1+Inputs!$B$48)^(D3-1)*(Inputs!$C$35+(1-Inputs!$C$35)*D6/Inputs!$B$6),0) -> 0 | E14: =IF(E1>=Inputs!$B$10-Inputs!$D$35,-(Inputs!$B$35*Inputs!$B$6/12)*(1+Inputs!$B$48)^(E3-1)*(Inputs!$C$35+(1-Inputs!$C$35)*E6/Inputs!$B$6),0) -> 0 | F14: =IF(F1>=Inputs!$B$10-Inputs!$D$35,-(Inputs!$B$35*Inputs!$B$6/12)*(1+Inputs!$B$48)^(F3-1)*(Inputs!$C$35+(1-Inputs!$C$35)*F6/Inputs!$B$6),0) -> 0 | G14: =IF(G1>=Inputs!$B$10-Inputs!$D$35,-(Inputs!$B$35*Inputs!$B$6/12)*(1+Inputs!$B$48)^(G3-1)*(Inputs!$C$35+(1-Inputs!$C$35)*G6/Inputs!$B$6),0) -> 0 | H14: =IF(H1>=Inputs!$B$10-Inputs!$D$35,-(Inputs!$B$35*Inputs!$B$6/12)*(1+Inputs!$B$48)^(H3-1)*(Inputs!$C$35+(1-Inputs!$C$35)*H6/Inputs!$B$6),0) -> 0 | I14: =IF(I1>=Inputs!$B$10-Inputs!$D$35,-(Inputs!$B$35*Inputs!$B$6/12)*(1+Inputs!$B$48)^(I3-1)*(Inputs!$C$35+(1-Inputs!$C$35)*I6/Inputs!$B$6),0) -> 0 | J14: =IF(J1>=Inputs!$B$10-Inputs!$D$35,-(Inputs!$B$35*Inputs!$B$6/12)*(1+Inputs!$B$48)^(J3-1)*(Inputs!$C$35+(1-Inputs!$C$35)*J6/Inputs!$B$6),0) -> 0 | ... CT14: =IF(CT1>=Inputs!$B$10-Inputs!$D$35,-(Inputs!$B$35*Inputs!$B$6/12)*(1+Inputs!$B$48)^(CT3-1)*(Inputs!$C$35+(1-Inputs!$C$35)*CT6/Inputs!$B$6),0) -> -48926.306
B15: General & Administrative | C15: =IF(C1>=Inputs!$B$10-Inputs!$D$36,-(Inputs!$B$36*Inputs!$B$6/12)*(1+Inputs!$B$48)^(C3-1)*(Inputs!$C$36+(1-Inputs!$C$36)*C6/Inputs!$B$6),0) -> 0 | D15: =IF(D1>=Inputs!$B$10-Inputs!$D$36,-(Inputs!$B$36*Inputs!$B$6/12)*(1+Inputs!$B$48)^(D3-1)*(Inputs!$C$36+(1-Inputs!$C$36)*D6/Inputs!$B$6),0) -> 0 | E15: =IF(E1>=Inputs!$B$10-Inputs!$D$36,-(Inputs!$B$36*Inputs!$B$6/12)*(1+Inputs!$B$48)^(E3-1)*(Inputs!$C$36+(1-Inputs!$C$36)*E6/Inputs!$B$6),0) -> 0 | F15: =IF(F1>=Inputs!$B$10-Inputs!$D$36,-(Inputs!$B$36*Inputs!$B$6/12)*(1+Inputs!$B$48)^(F3-1)*(Inputs!$C$36+(1-Inputs!$C$36)*F6/Inputs!$B$6),0) -> 0 | G15: =IF(G1>=Inputs!$B$10-Inputs!$D$36,-(Inputs!$B$36*Inputs!$B$6/12)*(1+Inputs!$B$48)^(G3-1)*(Inputs!$C$36+(1-Inputs!$C$36)*G6/Inputs!$B$6),0) -> 0 | H15: =IF(H1>=Inputs!$B$10-Inputs!$D$36,-(Inputs!$B$36*Inputs!$B$6/12)*(1+Inputs!$B$48)^(H3-1)*(Inputs!$C$36+(1-Inputs!$C$36)*H6/Inputs!$B$6),0) -> 0 | I15: =IF(I1>=Inputs!$B$10-Inputs!$D$36,-(Inputs!$B$36*Inputs!$B$6/12)*(1+Inputs!$B$48)^(I3-1)*(Inputs!$C$36+(1-Inputs!$C$36)*I6/Inputs!$B$6),0) -> 0 | J15: =IF(J1>=Inputs!$B$10-Inputs!$D$36,-(Inputs!$B$36*Inputs!$B$6/12)*(1+Inputs!$B$48)^(J3-1)*(Inputs!$C$36+(1-Inputs!$C$36)*J6/Inputs!$B$6),0) -> 0 | ... CT15: =IF(CT1>=Inputs!$B$10-Inputs!$D$36,-(Inputs!$B$36*Inputs!$B$6/12)*(1+Inputs!$B$48)^(CT3-1)*(Inputs!$C$36+(1-Inputs!$C$36)*CT6/Inputs!$B$6),0) -> -13693.66
B16: Marketing | C16: =IF(C1>=Inputs!$B$10-Inputs!$D$37,-(Inputs!$B$37*Inputs!$B$6/12)*(1+Inputs!$B$48)^(C3-1)*(Inputs!$C$37+(1-Inputs!$C$37)*C6/Inputs!$B$6),0) -> 0 | D16: =IF(D1>=Inputs!$B$10-Inputs!$D$37,-(Inputs!$B$37*Inputs!$B$6/12)*(1+Inputs!$B$48)^(D3-1)*(Inputs!$C$37+(1-Inputs!$C$37)*D6/Inputs!$B$6),0) -> 0 | E16: =IF(E1>=Inputs!$B$10-Inputs!$D$37,-(Inputs!$B$37*Inputs!$B$6/12)*(1+Inputs!$B$48)^(E3-1)*(Inputs!$C$37+(1-Inputs!$C$37)*E6/Inputs!$B$6),0) -> 0 | F16: =IF(F1>=Inputs!$B$10-Inputs!$D$37,-(Inputs!$B$37*Inputs!$B$6/12)*(1+Inputs!$B$48)^(F3-1)*(Inputs!$C$37+(1-Inputs!$C$37)*F6/Inputs!$B$6),0) -> 0 | G16: =IF(G1>=Inputs!$B$10-Inputs!$D$37,-(Inputs!$B$37*Inputs!$B$6/12)*(1+Inputs!$B$48)^(G3-1)*(Inputs!$C$37+(1-Inputs!$C$37)*G6/Inputs!$B$6),0) -> 0 | H16: =IF(H1>=Inputs!$B$10-Inputs!$D$37,-(Inputs!$B$37*Inputs!$B$6/12)*(1+Inputs!$B$48)^(H3-1)*(Inputs!$C$37+(1-Inputs!$C$37)*H6/Inputs!$B$6),0) -> 0 | I16: =IF(I1>=Inputs!$B$10-Inputs!$D$37,-(Inputs!$B$37*Inputs!$B$6/12)*(1+Inputs!$B$48)^(I3-1)*(Inputs!$C$37+(1-Inputs!$C$37)*I6/Inputs!$B$6),0) -> 0 | J16: =IF(J1>=Inputs!$B$10-Inputs!$D$37,-(Inputs!$B$37*Inputs!$B$6/12)*(1+Inputs!$B$48)^(J3-1)*(Inputs!$C$37+(1-Inputs!$C$37)*J6/Inputs!$B$6),0) -> 0 | ... CT16: =IF(CT1>=Inputs!$B$10-Inputs!$D$37,-(Inputs!$B$37*Inputs!$B$6/12)*(1+Inputs!$B$48)^(CT3-1)*(Inputs!$C$37+(1-Inputs!$C$37)*CT6/Inputs!$B$6),0) -> -11839.31
B17: Repairs & Maintenance | C17: =IF(C1>=Inputs!$B$10-Inputs!$D$38,-(Inputs!$B$38*Inputs!$B$6/12)*(1+Inputs!$B$48)^(C3-1)*(Inputs!$C$38+(1-Inputs!$C$38)*C6/Inputs!$B$6),0) -> 0 | D17: =IF(D1>=Inputs!$B$10-Inputs!$D$38,-(Inputs!$B$38*Inputs!$B$6/12)*(1+Inputs!$B$48)^(D3-1)*(Inputs!$C$38+(1-Inputs!$C$38)*D6/Inputs!$B$6),0) -> 0 | E17: =IF(E1>=Inputs!$B$10-Inputs!$D$38,-(Inputs!$B$38*Inputs!$B$6/12)*(1+Inputs!$B$48)^(E3-1)*(Inputs!$C$38+(1-Inputs!$C$38)*E6/Inputs!$B$6),0) -> 0 | F17: =IF(F1>=Inputs!$B$10-Inputs!$D$38,-(Inputs!$B$38*Inputs!$B$6/12)*(1+Inputs!$B$48)^(F3-1)*(Inputs!$C$38+(1-Inputs!$C$38)*F6/Inputs!$B$6),0) -> 0 | G17: =IF(G1>=Inputs!$B$10-Inputs!$D$38,-(Inputs!$B$38*Inputs!$B$6/12)*(1+Inputs!$B$48)^(G3-1)*(Inputs!$C$38+(1-Inputs!$C$38)*G6/Inputs!$B$6),0) -> 0 | H17: =IF(H1>=Inputs!$B$10-Inputs!$D$38,-(Inputs!$B$38*Inputs!$B$6/12)*(1+Inputs!$B$48)^(H3-1)*(Inputs!$C$38+(1-Inputs!$C$38)*H6/Inputs!$B$6),0) -> 0 | I17: =IF(I1>=Inputs!$B$10-Inputs!$D$38,-(Inputs!$B$38*Inputs!$B$6/12)*(1+Inputs!$B$48)^(I3-1)*(Inputs!$C$38+(1-Inputs!$C$38)*I6/Inputs!$B$6),0) -> 0 | J17: =IF(J1>=Inputs!$B$10-Inputs!$D$38,-(Inputs!$B$38*Inputs!$B$6/12)*(1+Inputs!$B$48)^(J3-1)*(Inputs!$C$38+(1-Inputs!$C$38)*J6/Inputs!$B$6),0) -> 0 | ... CT17: =IF(CT1>=Inputs!$B$10-Inputs!$D$38,-(Inputs!$B$38*Inputs!$B$6/12)*(1+Inputs!$B$48)^(CT3-1)*(Inputs!$C$38+(1-Inputs!$C$38)*CT6/Inputs!$B$6),0) -> -13869.395
B18: Contract Services | C18: =IF(C1>=Inputs!$B$10-Inputs!$D$39,-(Inputs!$B$39*Inputs!$B$6/12)*(1+Inputs!$B$48)^(C3-1)*(Inputs!$C$39+(1-Inputs!$C$39)*C6/Inputs!$B$6),0) -> 0 | D18: =IF(D1>=Inputs!$B$10-Inputs!$D$39,-(Inputs!$B$39*Inputs!$B$6/12)*(1+Inputs!$B$48)^(D3-1)*(Inputs!$C$39+(1-Inputs!$C$39)*D6/Inputs!$B$6),0) -> 0 | E18: =IF(E1>=Inputs!$B$10-Inputs!$D$39,-(Inputs!$B$39*Inputs!$B$6/12)*(1+Inputs!$B$48)^(E3-1)*(Inputs!$C$39+(1-Inputs!$C$39)*E6/Inputs!$B$6),0) -> 0 | F18: =IF(F1>=Inputs!$B$10-Inputs!$D$39,-(Inputs!$B$39*Inputs!$B$6/12)*(1+Inputs!$B$48)^(F3-1)*(Inputs!$C$39+(1-Inputs!$C$39)*F6/Inputs!$B$6),0) -> 0 | G18: =IF(G1>=Inputs!$B$10-Inputs!$D$39,-(Inputs!$B$39*Inputs!$B$6/12)*(1+Inputs!$B$48)^(G3-1)*(Inputs!$C$39+(1-Inputs!$C$39)*G6/Inputs!$B$6),0) -> 0 | H18: =IF(H1>=Inputs!$B$10-Inputs!$D$39,-(Inputs!$B$39*Inputs!$B$6/12)*(1+Inputs!$B$48)^(H3-1)*(Inputs!$C$39+(1-Inputs!$C$39)*H6/Inputs!$B$6),0) -> 0 | I18: =IF(I1>=Inputs!$B$10-Inputs!$D$39,-(Inputs!$B$39*Inputs!$B$6/12)*(1+Inputs!$B$48)^(I3-1)*(Inputs!$C$39+(1-Inputs!$C$39)*I6/Inputs!$B$6),0) -> 0 | J18: =IF(J1>=Inputs!$B$10-Inputs!$D$39,-(Inputs!$B$39*Inputs!$B$6/12)*(1+Inputs!$B$48)^(J3-1)*(Inputs!$C$39+(1-Inputs!$C$39)*J6/Inputs!$B$6),0) -> 0 | ... CT18: =IF(CT1>=Inputs!$B$10-Inputs!$D$39,-(Inputs!$B$39*Inputs!$B$6/12)*(1+Inputs!$B$48)^(CT3-1)*(Inputs!$C$39+(1-Inputs!$C$39)*CT6/Inputs!$B$6),0) -> 0
B19: Utilities | C19: =IF(C1>=Inputs!$B$10-Inputs!$D$40,-(Inputs!$B$40*Inputs!$B$6/12)*(1+Inputs!$B$48)^(C3-1)*(Inputs!$C$40+(1-Inputs!$C$40)*C6/Inputs!$B$6),0) -> 0 | D19: =IF(D1>=Inputs!$B$10-Inputs!$D$40,-(Inputs!$B$40*Inputs!$B$6/12)*(1+Inputs!$B$48)^(D3-1)*(Inputs!$C$40+(1-Inputs!$C$40)*D6/Inputs!$B$6),0) -> 0 | E19: =IF(E1>=Inputs!$B$10-Inputs!$D$40,-(Inputs!$B$40*Inputs!$B$6/12)*(1+Inputs!$B$48)^(E3-1)*(Inputs!$C$40+(1-Inputs!$C$40)*E6/Inputs!$B$6),0) -> 0 | F19: =IF(F1>=Inputs!$B$10-Inputs!$D$40,-(Inputs!$B$40*Inputs!$B$6/12)*(1+Inputs!$B$48)^(F3-1)*(Inputs!$C$40+(1-Inputs!$C$40)*F6/Inputs!$B$6),0) -> 0 | G19: =IF(G1>=Inputs!$B$10-Inputs!$D$40,-(Inputs!$B$40*Inputs!$B$6/12)*(1+Inputs!$B$48)^(G3-1)*(Inputs!$C$40+(1-Inputs!$C$40)*G6/Inputs!$B$6),0) -> 0 | H19: =IF(H1>=Inputs!$B$10-Inputs!$D$40,-(Inputs!$B$40*Inputs!$B$6/12)*(1+Inputs!$B$48)^(H3-1)*(Inputs!$C$40+(1-Inputs!$C$40)*H6/Inputs!$B$6),0) -> 0 | I19: =IF(I1>=Inputs!$B$10-Inputs!$D$40,-(Inputs!$B$40*Inputs!$B$6/12)*(1+Inputs!$B$48)^(I3-1)*(Inputs!$C$40+(1-Inputs!$C$40)*I6/Inputs!$B$6),0) -> 0 | J19: =IF(J1>=Inputs!$B$10-Inputs!$D$40,-(Inputs!$B$40*Inputs!$B$6/12)*(1+Inputs!$B$48)^(J3-1)*(Inputs!$C$40+(1-Inputs!$C$40)*J6/Inputs!$B$6),0) -> 0 | ... CT19: =IF(CT1>=Inputs!$B$10-Inputs!$D$40,-(Inputs!$B$40*Inputs!$B$6/12)*(1+Inputs!$B$48)^(CT3-1)*(Inputs!$C$40+(1-Inputs!$C$40)*CT6/Inputs!$B$6),0) -> -20785.121
B20: Other | C20: =IF(C1>=Inputs!$B$10-Inputs!$D$41,-(Inputs!$B$41*Inputs!$B$6/12)*(1+Inputs!$B$48)^(C3-1)*(Inputs!$C$41+(1-Inputs!$C$41)*C6/Inputs!$B$6),0) -> 0 | D20: =IF(D1>=Inputs!$B$10-Inputs!$D$41,-(Inputs!$B$41*Inputs!$B$6/12)*(1+Inputs!$B$48)^(D3-1)*(Inputs!$C$41+(1-Inputs!$C$41)*D6/Inputs!$B$6),0) -> 0 | E20: =IF(E1>=Inputs!$B$10-Inputs!$D$41,-(Inputs!$B$41*Inputs!$B$6/12)*(1+Inputs!$B$48)^(E3-1)*(Inputs!$C$41+(1-Inputs!$C$41)*E6/Inputs!$B$6),0) -> 0 | F20: =IF(F1>=Inputs!$B$10-Inputs!$D$41,-(Inputs!$B$41*Inputs!$B$6/12)*(1+Inputs!$B$48)^(F3-1)*(Inputs!$C$41+(1-Inputs!$C$41)*F6/Inputs!$B$6),0) -> 0 | G20: =IF(G1>=Inputs!$B$10-Inputs!$D$41,-(Inputs!$B$41*Inputs!$B$6/12)*(1+Inputs!$B$48)^(G3-1)*(Inputs!$C$41+(1-Inputs!$C$41)*G6/Inputs!$B$6),0) -> 0 | H20: =IF(H1>=Inputs!$B$10-Inputs!$D$41,-(Inputs!$B$41*Inputs!$B$6/12)*(1+Inputs!$B$48)^(H3-1)*(Inputs!$C$41+(1-Inputs!$C$41)*H6/Inputs!$B$6),0) -> 0 | I20: =IF(I1>=Inputs!$B$10-Inputs!$D$41,-(Inputs!$B$41*Inputs!$B$6/12)*(1+Inputs!$B$48)^(I3-1)*(Inputs!$C$41+(1-Inputs!$C$41)*I6/Inputs!$B$6),0) -> 0 | J20: =IF(J1>=Inputs!$B$10-Inputs!$D$41,-(Inputs!$B$41*Inputs!$B$6/12)*(1+Inputs!$B$48)^(J3-1)*(Inputs!$C$41+(1-Inputs!$C$41)*J6/Inputs!$B$6),0) -> 0 | ... CT20: =IF(CT1>=Inputs!$B$10-Inputs!$D$41,-(Inputs!$B$41*Inputs!$B$6/12)*(1+Inputs!$B$48)^(CT3-1)*(Inputs!$C$41+(1-Inputs!$C$41)*CT6/Inputs!$B$6),0) -> -2785.8039
B21: Insurance | C21: =IF(C1>=Inputs!$B$10-Inputs!$D$42,-(Inputs!$B$42*Inputs!$B$6/12)*(1+Inputs!$B$48)^(C3-1)*(Inputs!$C$42+(1-Inputs!$C$42)*C6/Inputs!$B$6),0) -> 0 | D21: =IF(D1>=Inputs!$B$10-Inputs!$D$42,-(Inputs!$B$42*Inputs!$B$6/12)*(1+Inputs!$B$48)^(D3-1)*(Inputs!$C$42+(1-Inputs!$C$42)*D6/Inputs!$B$6),0) -> 0 | E21: =IF(E1>=Inputs!$B$10-Inputs!$D$42,-(Inputs!$B$42*Inputs!$B$6/12)*(1+Inputs!$B$48)^(E3-1)*(Inputs!$C$42+(1-Inputs!$C$42)*E6/Inputs!$B$6),0) -> 0 | F21: =IF(F1>=Inputs!$B$10-Inputs!$D$42,-(Inputs!$B$42*Inputs!$B$6/12)*(1+Inputs!$B$48)^(F3-1)*(Inputs!$C$42+(1-Inputs!$C$42)*F6/Inputs!$B$6),0) -> 0 | G21: =IF(G1>=Inputs!$B$10-Inputs!$D$42,-(Inputs!$B$42*Inputs!$B$6/12)*(1+Inputs!$B$48)^(G3-1)*(Inputs!$C$42+(1-Inputs!$C$42)*G6/Inputs!$B$6),0) -> 0 | H21: =IF(H1>=Inputs!$B$10-Inputs!$D$42,-(Inputs!$B$42*Inputs!$B$6/12)*(1+Inputs!$B$48)^(H3-1)*(Inputs!$C$42+(1-Inputs!$C$42)*H6/Inputs!$B$6),0) -> 0 | I21: =IF(I1>=Inputs!$B$10-Inputs!$D$42,-(Inputs!$B$42*Inputs!$B$6/12)*(1+Inputs!$B$48)^(I3-1)*(Inputs!$C$42+(1-Inputs!$C$42)*I6/Inputs!$B$6),0) -> 0 | J21: =IF(J1>=Inputs!$B$10-Inputs!$D$42,-(Inputs!$B$42*Inputs!$B$6/12)*(1+Inputs!$B$48)^(J3-1)*(Inputs!$C$42+(1-Inputs!$C$42)*J6/Inputs!$B$6),0) -> 0 | ... CT21: =IF(CT1>=Inputs!$B$10-Inputs!$D$42,-(Inputs!$B$42*Inputs!$B$6/12)*(1+Inputs!$B$48)^(CT3-1)*(Inputs!$C$42+(1-Inputs!$C$42)*CT6/Inputs!$B$6),0) -> -57056.916
B22: Property Taxes | C22: =IF(C1>=Inputs!$B$9+Inputs!$B$8,-Inputs!$B$44/12*(1+Inputs!$B$48)^(C3-1),-Inputs!$B$43/12) -> -2500 | D22: =IF(D1>=Inputs!$B$9+Inputs!$B$8,-Inputs!$B$44/12*(1+Inputs!$B$48)^(D3-1),-Inputs!$B$43/12) -> -2500 | E22: =IF(E1>=Inputs!$B$9+Inputs!$B$8,-Inputs!$B$44/12*(1+Inputs!$B$48)^(E3-1),-Inputs!$B$43/12) -> -2500 | F22: =IF(F1>=Inputs!$B$9+Inputs!$B$8,-Inputs!$B$44/12*(1+Inputs!$B$48)^(F3-1),-Inputs!$B$43/12) -> -2500 | G22: =IF(G1>=Inputs!$B$9+Inputs!$B$8,-Inputs!$B$44/12*(1+Inputs!$B$48)^(G3-1),-Inputs!$B$43/12) -> -2500 | H22: =IF(H1>=Inputs!$B$9+Inputs!$B$8,-Inputs!$B$44/12*(1+Inputs!$B$48)^(H3-1),-Inputs!$B$43/12) -> -2500 | I22: =IF(I1>=Inputs!$B$9+Inputs!$B$8,-Inputs!$B$44/12*(1+Inputs!$B$48)^(I3-1),-Inputs!$B$43/12) -> -2500 | J22: =IF(J1>=Inputs!$B$9+Inputs!$B$8,-Inputs!$B$44/12*(1+Inputs!$B$48)^(J3-1),-Inputs!$B$43/12) -> -2500 | ... CT22: =IF(CT1>=Inputs!$B$9+Inputs!$B$8,-Inputs!$B$44/12*(1+Inputs!$B$48)^(CT3-1),-Inputs!$B$43/12) -> -39622.858
B23: Management Fee | C23: =-MAX(C12,0)*Inputs!$B$45 -> 0 | D23: =-MAX(D12,0)*Inputs!$B$45 -> 0 | E23: =-MAX(E12,0)*Inputs!$B$45 -> 0 | F23: =-MAX(F12,0)*Inputs!$B$45 -> 0 | G23: =-MAX(G12,0)*Inputs!$B$45 -> 0 | H23: =-MAX(H12,0)*Inputs!$B$45 -> 0 | I23: =-MAX(I12,0)*Inputs!$B$45 -> 0 | J23: =-MAX(J12,0)*Inputs!$B$45 -> 0 | ... CT23: =-MAX(CT12,0)*Inputs!$B$45 -> -18053.871
B24: Total Operating Expenses | C24: =SUM(C14:C23) -> -2500 | D24: =SUM(D14:D23) -> -2500 | E24: =SUM(E14:E23) -> -2500 | F24: =SUM(F14:F23) -> -2500 | G24: =SUM(G14:G23) -> -2500 | H24: =SUM(H14:H23) -> -2500 | I24: =SUM(I14:I23) -> -2500 | J24: =SUM(J14:J23) -> -2500 | ... CT24: =SUM(CT14:CT23) -> -226633.24
B26: Net Operating Income | C26: =C12+C24 -> -2500 | D26: =D12+D24 -> -2500 | E26: =E12+E24 -> -2500 | F26: =F12+F24 -> -2500 | G26: =G12+G24 -> -2500 | H26: =H12+H24 -> -2500 | I26: =I12+I24 -> -2500 | J26: =J12+J24 -> -2500 | ... CT26: =CT12+CT24 -> 375162.44
B27: Capital Expense Reserve | C27: =IF(C1>=Inputs!$B$13,-(Inputs!$B$6*Inputs!$B$47/12)*(1+Inputs!$B$48)^(C3-1),0) -> 0 | D27: =IF(D1>=Inputs!$B$13,-(Inputs!$B$6*Inputs!$B$47/12)*(1+Inputs!$B$48)^(D3-1),0) -> 0 | E27: =IF(E1>=Inputs!$B$13,-(Inputs!$B$6*Inputs!$B$47/12)*(1+Inputs!$B$48)^(E3-1),0) -> 0 | F27: =IF(F1>=Inputs!$B$13,-(Inputs!$B$6*Inputs!$B$47/12)*(1+Inputs!$B$48)^(F3-1),0) -> 0 | G27: =IF(G1>=Inputs!$B$13,-(Inputs!$B$6*Inputs!$B$47/12)*(1+Inputs!$B$48)^(G3-1),0) -> 0 | H27: =IF(H1>=Inputs!$B$13,-(Inputs!$B$6*Inputs!$B$47/12)*(1+Inputs!$B$48)^(H3-1),0) -> 0 | I27: =IF(I1>=Inputs!$B$13,-(Inputs!$B$6*Inputs!$B$47/12)*(1+Inputs!$B$48)^(I3-1),0) -> 0 | J27: =IF(J1>=Inputs!$B$13,-(Inputs!$B$6*Inputs!$B$47/12)*(1+Inputs!$B$48)^(J3-1),0) -> 0 | ... CT27: =IF(CT1>=Inputs!$B$13,-(Inputs!$B$6*Inputs!$B$47/12)*(1+Inputs!$B$48)^(CT3-1),0) -> -7132.1145
B28: Asset Management Fee | C28: =-MAX(C12,0)*Inputs!$B$46 -> 0 | D28: =-MAX(D12,0)*Inputs!$B$46 -> 0 | E28: =-MAX(E12,0)*Inputs!$B$46 -> 0 | F28: =-MAX(F12,0)*Inputs!$B$46 -> 0 | G28: =-MAX(G12,0)*Inputs!$B$46 -> 0 | H28: =-MAX(H12,0)*Inputs!$B$46 -> 0 | I28: =-MAX(I12,0)*Inputs!$B$46 -> 0 | J28: =-MAX(J12,0)*Inputs!$B$46 -> 0 | ... CT28: =-MAX(CT12,0)*Inputs!$B$46 -> -6017.9568
B29: Cash Flow Before Debt Service | C29: =C26+C27+C28 -> -2500 | D29: =D26+D27+D28 -> -2500 | E29: =E26+E27+E28 -> -2500 | F29: =F26+F27+F28 -> -2500 | G29: =G26+G27+G28 -> -2500 | H29: =H26+H27+H28 -> -2500 | I29: =I26+I27+I28 -> -2500 | J29: =J26+J27+J28 -> -2500 | ... CT29: =CT26+CT27+CT28 -> 362012.37
B31: Land & Closing Costs | C31: =IF(C1=1,-(Inputs!$B$2+Inputs!$B$2*Inputs!$B$3),0) -> -6800625 | D31: =IF(D1=1,-(Inputs!$B$2+Inputs!$B$2*Inputs!$B$3),0) -> 0 | E31: =IF(E1=1,-(Inputs!$B$2+Inputs!$B$2*Inputs!$B$3),0) -> 0 | F31: =IF(F1=1,-(Inputs!$B$2+Inputs!$B$2*Inputs!$B$3),0) -> 0 | G31: =IF(G1=1,-(Inputs!$B$2+Inputs!$B$2*Inputs!$B$3),0) -> 0 | H31: =IF(H1=1,-(Inputs!$B$2+Inputs!$B$2*Inputs!$B$3),0) -> 0 | I31: =IF(I1=1,-(Inputs!$B$2+Inputs!$B$2*Inputs!$B$3),0) -> 0 | J31: =IF(J1=1,-(Inputs!$B$2+Inputs!$B$2*Inputs!$B$3),0) -> 0 | ... CT31: =IF(CT1=1,-(Inputs!$B$2+Inputs!$B$2*Inputs!$B$3),0) -> 0
B32: Construction Spend | C32: =-'Construction Budget'!F33 -> -195800 | D32: =-'Construction Budget'!G33 -> -986005.98 | E32: =-'Construction Budget'!H33 -> -1252709.3 | F32: =-'Construction Budget'!I33 -> -1556349 | G32: =-'Construction Budget'!J33 -> -1888585.5 | H32: =-'Construction Budget'!K33 -> -2236411.5 | I32: =-'Construction Budget'!L33 -> -2582627.9 | J32: =-'Construction Budget'!M33 -> -2907044.9 | ... CT32: =-'Construction Budget'!CW33 -> 0
B33: Construction Loan Fee | C33: =IF(C1=1,-Inputs!$B$85,0) -> -235963.17 | D33: =IF(D1=1,-Inputs!$B$85,0) -> 0 | E33: =IF(E1=1,-Inputs!$B$85,0) -> 0 | F33: =IF(F1=1,-Inputs!$B$85,0) -> 0 | G33: =IF(G1=1,-Inputs!$B$85,0) -> 0 | H33: =IF(H1=1,-Inputs!$B$85,0) -> 0 | I33: =IF(I1=1,-Inputs!$B$85,0) -> 0 | J33: =IF(J1=1,-Inputs!$B$85,0) -> 0 | ... CT33: =IF(CT1=1,-Inputs!$B$85,0) -> 0
B34: Total Development Cost | C34: =SUM(C31:C33) -> -7232388.2 | D34: =SUM(D31:D33) -> -986005.98 | E34: =SUM(E31:E33) -> -1252709.3 | F34: =SUM(F31:F33) -> -1556349 | G34: =SUM(G31:G33) -> -1888585.5 | H34: =SUM(H31:H33) -> -2236411.5 | I34: =SUM(I31:I33) -> -2582627.9 | J34: =SUM(J31:J33) -> -2907044.9 | ... CT34: =SUM(CT31:CT33) -> 0
B36: Funding Need (pre-refi) | C36: =IF(C1<Inputs!$B$58,-C34+MAX(0,-C29),0) -> 7234888.2 | D36: =IF(D1<Inputs!$B$58,-D34+MAX(0,-D29),0) -> 988505.98 | E36: =IF(E1<Inputs!$B$58,-E34+MAX(0,-E29),0) -> 1255209.3 | F36: =IF(F1<Inputs!$B$58,-F34+MAX(0,-F29),0) -> 1558849 | G36: =IF(G1<Inputs!$B$58,-G34+MAX(0,-G29),0) -> 1891085.5 | H36: =IF(H1<Inputs!$B$58,-H34+MAX(0,-H29),0) -> 2238911.5 | I36: =IF(I1<Inputs!$B$58,-I34+MAX(0,-I29),0) -> 2585127.9 | J36: =IF(J1<Inputs!$B$58,-J34+MAX(0,-J29),0) -> 2909544.9 | ... CT36: =IF(CT1<Inputs!$B$58,-CT34+MAX(0,-CT29),0) -> 0
B37: Equity Remaining - Beg | C37: =IF(C1=1,Inputs!$B$87,0) -> 14174996 | D37: =IF(D1=1,Inputs!$B$87,C39) -> 6940107.9 | E37: =IF(E1=1,Inputs!$B$87,D39) -> 5951601.9 | F37: =IF(F1=1,Inputs!$B$87,E39) -> 4696392.6 | G37: =IF(G1=1,Inputs!$B$87,F39) -> 3137543.6 | H37: =IF(H1=1,Inputs!$B$87,G39) -> 1246458.1 | I37: =IF(I1=1,Inputs!$B$87,H39) -> 0 | J37: =IF(J1=1,Inputs!$B$87,I39) -> 0 | K37: =IF(K1=1,Inputs!$B$87,J39) -> 0 | ... CT37: =IF(CT1=1,Inputs!$B$87,CS39) -> 0
B38: Equity Draw | C38: =MIN(C37,C36) -> 7234888.2 | D38: =MIN(D37,D36) -> 988505.98 | E38: =MIN(E37,E36) -> 1255209.3 | F38: =MIN(F37,F36) -> 1558849 | G38: =MIN(G37,G36) -> 1891085.5 | H38: =MIN(H37,H36) -> 1246458.1 | I38: =MIN(I37,I36) -> 0 | J38: =MIN(J37,J36) -> 0 | ... CT38: =MIN(CT37,CT36) -> 0
B39: Equity Remaining - End | C39: =C37-C38 -> 6940107.9 | D39: =D37-D38 -> 5951601.9 | E39: =E37-E38 -> 4696392.6 | F39: =F37-F38 -> 3137543.6 | G39: =G37-G38 -> 1246458.1 | H39: =H37-H38 -> 0 | I39: =I37-I38 -> 0 | J39: =J37-J38 -> 0 | ... CT39: =CT37-CT38 -> 0
B40: Constr Loan Balance - Beg | C40: =0 -> 0 | D40: =IF(D1=1,0,C44) -> 0 | E40: =IF(E1=1,0,D44) -> 0 | F40: =IF(F1=1,0,E44) -> 0 | G40: =IF(G1=1,0,F44) -> 0 | H40: =IF(H1=1,0,G44) -> 0 | I40: =IF(I1=1,0,H44) -> 992453.38 | J40: =IF(J1=1,0,I44) -> 3583577.4 | K40: =IF(K1=1,0,J44) -> 6514773 | ... CT40: =IF(CT1=1,0,CS44) -> 0
B41: Constr Loan Draw | C41: =IF(C1<Inputs!$B$58,C36-C38,0) -> 0 | D41: =IF(D1<Inputs!$B$58,D36-D38,0) -> 0 | E41: =IF(E1<Inputs!$B$58,E36-E38,0) -> 0 | F41: =IF(F1<Inputs!$B$58,F36-F38,0) -> 0 | G41: =IF(G1<Inputs!$B$58,G36-G38,0) -> 0 | H41: =IF(H1<Inputs!$B$58,H36-H38,0) -> 992453.38 | I41: =IF(I1<Inputs!$B$58,I36-I38,0) -> 2585127.9 | J41: =IF(J1<Inputs!$B$58,J36-J38,0) -> 2909544.9 | ... CT41: =IF(CT1<Inputs!$B$58,CT36-CT38,0) -> 0
B42: Capitalized Interest | C42: =IF(C1<=Inputs!$B$58,C40*Inputs!$B$54/12,0) -> 0 | D42: =IF(D1<=Inputs!$B$58,D40*Inputs!$B$54/12,0) -> 0 | E42: =IF(E1<=Inputs!$B$58,E40*Inputs!$B$54/12,0) -> 0 | F42: =IF(F1<=Inputs!$B$58,F40*Inputs!$B$54/12,0) -> 0 | G42: =IF(G1<=Inputs!$B$58,G40*Inputs!$B$54/12,0) -> 0 | H42: =IF(H1<=Inputs!$B$58,H40*Inputs!$B$54/12,0) -> 0 | I42: =IF(I1<=Inputs!$B$58,I40*Inputs!$B$54/12,0) -> 5996.0725 | J42: =IF(J1<=Inputs!$B$58,J40*Inputs!$B$54/12,0) -> 21650.78 | ... CT42: =IF(CT1<=Inputs!$B$58,CT40*Inputs!$B$54/12,0) -> 0
B43: Constr Loan Payoff | C43: =IF(C1=Inputs!$B$58,-(C40+C41+C42),0) -> 0 | D43: =IF(D1=Inputs!$B$58,-(D40+D41+D42),0) -> 0 | E43: =IF(E1=Inputs!$B$58,-(E40+E41+E42),0) -> 0 | F43: =IF(F1=Inputs!$B$58,-(F40+F41+F42),0) -> 0 | G43: =IF(G1=Inputs!$B$58,-(G40+G41+G42),0) -> 0 | H43: =IF(H1=Inputs!$B$58,-(H40+H41+H42),0) -> 0 | I43: =IF(I1=Inputs!$B$58,-(I40+I41+I42),0) -> 0 | J43: =IF(J1=Inputs!$B$58,-(J40+J41+J42),0) -> 0 | ... CT43: =IF(CT1=Inputs!$B$58,-(CT40+CT41+CT42),0) -> 0
B44: Constr Loan Balance - End | C44: =SUM(C40:C43) -> 0 | D44: =SUM(D40:D43) -> 0 | E44: =SUM(E40:E43) -> 0 | F44: =SUM(F40:F43) -> 0 | G44: =SUM(G40:G43) -> 0 | H44: =SUM(H40:H43) -> 992453.38 | I44: =SUM(I40:I43) -> 3583577.4 | J44: =SUM(J40:J43) -> 6514773 | ... CT44: =SUM(CT40:CT43) -> 0
B46: Refi Value (NOI x 12 / Cap) | C46: =IF(C1=Inputs!$B$58,C26*12/Inputs!$B$59,0) -> 0 | D46: =IF(D1=Inputs!$B$58,D26*12/Inputs!$B$59,0) -> 0 | E46: =IF(E1=Inputs!$B$58,E26*12/Inputs!$B$59,0) -> 0 | F46: =IF(F1=Inputs!$B$58,F26*12/Inputs!$B$59,0) -> 0 | G46: =IF(G1=Inputs!$B$58,G26*12/Inputs!$B$59,0) -> 0 | H46: =IF(H1=Inputs!$B$58,H26*12/Inputs!$B$59,0) -> 0 | I46: =IF(I1=Inputs!$B$58,I26*12/Inputs!$B$59,0) -> 0 | J46: =IF(J1=Inputs!$B$58,J26*12/Inputs!$B$59,0) -> 0 | ... CT46: =IF(CT1=Inputs!$B$58,CT26*12/Inputs!$B$59,0) -> 0
...

Sheet Waterfall
A1: LP / GP WATERFALL (Monthly)
B2: LP Capital (Cash) | C2: =Inputs!$B$88 -> 14174996
B3: GP Capital (Cash) | C3: =Inputs!$B$89 -> 0
B4: GP In-Kind Credit | C4: =Inputs!$B$90 -> 0
B6: Month | C6: ='Monthly CF'!C1 -> 1 | D6: ='Monthly CF'!D1 -> 2 | E6: ='Monthly CF'!E1 -> 3 | F6: ='Monthly CF'!F1 -> 4 | G6: ='Monthly CF'!G1 -> 5 | H6: ='Monthly CF'!H1 -> 6 | I6: ='Monthly CF'!I1 -> 7 | J6: ='Monthly CF'!J1 -> 8 | ... CT6: ='Monthly CF'!CT1 -> 96
B7: Date | C7: ='Monthly CF'!C2 -> 46265 | D7: ='Monthly CF'!D2 -> 46295 | E7: ='Monthly CF'!E2 -> 46326 | F7: ='Monthly CF'!F2 -> 46356 | G7: ='Monthly CF'!G2 -> 46387 | H7: ='Monthly CF'!H2 -> 46418 | I7: ='Monthly CF'!I2 -> 46446 | J7: ='Monthly CF'!J2 -> 46477 | ... CT7: ='Monthly CF'!CT2 -> 49156
B8: Contribution (Equity Draw) | C8: ='Monthly CF'!C38 -> 7234888.2 | D8: ='Monthly CF'!D38 -> 988505.98 | E8: ='Monthly CF'!E38 -> 1255209.3 | F8: ='Monthly CF'!F38 -> 1558849 | G8: ='Monthly CF'!G38 -> 1891085.5 | H8: ='Monthly CF'!H38 -> 1246458.1 | I8: ='Monthly CF'!I38 -> 0 | J8: ='Monthly CF'!J38 -> 0 | ... CT8: ='Monthly CF'!CT38 -> 0
B9: LP Contribution | C9: =C8*Inputs!$B$75 -> 7234888.2 | D9: =D8*Inputs!$B$75 -> 988505.98 | E9: =E8*Inputs!$B$75 -> 1255209.3 | F9: =F8*Inputs!$B$75 -> 1558849 | G9: =G8*Inputs!$B$75 -> 1891085.5 | H9: =H8*Inputs!$B$75 -> 1246458.1 | I9: =I8*Inputs!$B$75 -> 0 | J9: =J8*Inputs!$B$75 -> 0 | ... CT9: =CT8*Inputs!$B$75 -> 0
B10: GP Contribution | C10: =C8-C9 -> 0 | D10: =D8-D9 -> 0 | E10: =E8-E9 -> 0 | F10: =F8-F9 -> 0 | G10: =G8-G9 -> 0 | H10: =H8-H9 -> 0 | I10: =I8-I9 -> 0 | J10: =J8-J9 -> 0 | ... CT10: =CT8-CT9 -> 0
B11: Distributable Cash | C11: =MAX(0,'Monthly CF'!C61+C8) -> 0 | D11: =MAX(0,'Monthly CF'!D61+D8) -> 0 | E11: =MAX(0,'Monthly CF'!E61+E8) -> 0 | F11: =MAX(0,'Monthly CF'!F61+F8) -> 0 | G11: =MAX(0,'Monthly CF'!G61+G8) -> 0 | H11: =MAX(0,'Monthly CF'!H61+H8) -> 0 | I11: =MAX(0,'Monthly CF'!I61+I8) -> 0 | J11: =MAX(0,'Monthly CF'!J61+J8) -> 0 | ... CT11: =MAX(0,'Monthly CF'!CT61+CT8) -> 0
B13: Pref Owed - Beg | C13: =0 -> 0 | D13: =IF(D6=1,0,C16) -> 48232.588 | E13: =IF(E6=1,0,D16) -> 103055.22 | F13: =IF(F6=1,0,E16) -> 166245.91 | G13: =IF(G6=1,0,F16) -> 239828.92 | H13: =IF(H6=1,0,G16) -> 326019.18 | I13: =IF(I6=1,0,H16) -> 420519.15 | J13: =IF(J6=1,0,I16) -> 515019.12 | K13: =IF(K6=1,0,J16) -> 609519.1 | ... CT13: =IF(CT6=1,0,CS16) -> 0
B14: Pref Accrual | C14: =C18*Inputs!$B$76/12 -> 48232.588 | D14: =D18*Inputs!$B$76/12 -> 54822.628 | E14: =E18*Inputs!$B$76/12 -> 63190.69 | F14: =F18*Inputs!$B$76/12 -> 73583.017 | G14: =G18*Inputs!$B$76/12 -> 86190.253 | H14: =H18*Inputs!$B$76/12 -> 94499.974 | I14: =I18*Inputs!$B$76/12 -> 94499.974 | J14: =J18*Inputs!$B$76/12 -> 94499.974 | ... CT14: =CT18*Inputs!$B$76/12 -> 0
B15: Pref Paid to LP | C15: =MIN(C11,C13+C14) -> 0 | D15: =MIN(D11,D13+D14) -> 0 | E15: =MIN(E11,E13+E14) -> 0 | F15: =MIN(F11,F13+F14) -> 0 | G15: =MIN(G11,G13+G14) -> 0 | H15: =MIN(H11,H13+H14) -> 0 | I15: =MIN(I11,I13+I14) -> 0 | J15: =MIN(J11,J13+J14) -> 0 | ... CT15: =MIN(CT11,CT13+CT14) -> 0
B16: Pref Owed - End | C16: =C13+C14-C15 -> 48232.588 | D16: =D13+D14-D15 -> 103055.22 | E16: =E13+E14-E15 -> 166245.91 | F16: =F13+F14-F15 -> 239828.92 | G16: =G13+G14-G15 -> 326019.18 | H16: =H13+H14-H15 -> 420519.15 | I16: =I13+I14-I15 -> 515019.12 | J16: =J13+J14-J15 -> 609519.1 | ... CT16: =CT13+CT14-CT15 -> 0
B18: LP Unreturned Capital - Beg | C18: =C9 -> 7234888.2 | D18: =IF(D6=1,D9,C20+D9) -> 8223394.2 | E18: =IF(E6=1,E9,D20+E9) -> 9478603.5 | F18: =IF(F6=1,F9,E20+F9) -> 11037452 | G18: =IF(G6=1,G9,F20+G9) -> 12928538 | H18: =IF(H6=1,H9,G20+H9) -> 14174996 | I18: =IF(I6=1,I9,H20+I9) -> 14174996 | J18: =IF(J6=1,J9,I20+J9) -> 14174996 | K18: =IF(K6=1,K9,J20+K9) -> 14174996 | ... CT18: =IF(CT6=1,CT9,CS20+CT9) -> 0
B19: LP Return of Capital | C19: =MIN(MAX(C11-C15,0),C18) -> 0 | D19: =MIN(MAX(D11-D15,0),D18) -> 0 | E19: =MIN(MAX(E11-E15,0),E18) -> 0 | F19: =MIN(MAX(F11-F15,0),F18) -> 0 | G19: =MIN(MAX(G11-G15,0),G18) -> 0 | H19: =MIN(MAX(H11-H15,0),H18) -> 0 | I19: =MIN(MAX(I11-I15,0),I18) -> 0 | J19: =MIN(MAX(J11-J15,0),J18) -> 0 | ... CT19: =MIN(MAX(CT11-CT15,0),CT18) -> 0
B20: LP Unreturned - End | C20: =C18-C19 -> 7234888.2 | D20: =D18-D19 -> 8223394.2 | E20: =E18-E19 -> 9478603.5 | F20: =F18-F19 -> 11037452 | G20: =G18-G19 -> 12928538 | H20: =H18-H19 -> 14174996 | I20: =I18-I19 -> 14174996 | J20: =J18-J19 -> 14174996 | ... CT20: =CT18-CT19 -> 0
B21: GP Unreturned Capital - Beg | C21: =C10+IF(Inputs!$B$78="On",$C$4,0) -> 0 | D21: =IF(D6=1,D10+IF(Inputs!$B$78="On",$C$4,0),C23+D10) -> 0 | E21: =IF(E6=1,E10+IF(Inputs!$B$78="On",$C$4,0),D23+E10) -> 0 | F21: =IF(F6=1,F10+IF(Inputs!$B$78="On",$C$4,0),E23+F10) -> 0 | G21: =IF(G6=1,G10+IF(Inputs!$B$78="On",$C$4,0),F23+G10) -> 0 | H21: =IF(H6=1,H10+IF(Inputs!$B$78="On",$C$4,0),G23+H10) -> 0 | I21: =IF(I6=1,I10+IF(Inputs!$B$78="On",$C$4,0),H23+I10) -> 0 | J21: =IF(J6=1,J10+IF(Inputs!$B$78="On",$C$4,0),I23+J10) -> 0 | K21: =IF(K6=1,K10+IF(Inputs!$B$78="On",$C$4,0),J23+K10) -> 0 | ... CT21: =IF(CT6=1,CT10+IF(Inputs!$B$78="On",$C$4,0),CS23+CT10) -> 0
B22: GP Return of Capital | C22: =MIN(MAX(C11-C15-C19,0),C21) -> 0 | D22: =MIN(MAX(D11-D15-D19,0),D21) -> 0 | E22: =MIN(MAX(E11-E15-E19,0),E21) -> 0 | F22: =MIN(MAX(F11-F15-F19,0),F21) -> 0 | G22: =MIN(MAX(G11-G15-G19,0),G21) -> 0 | H22: =MIN(MAX(H11-H15-H19,0),H21) -> 0 | I22: =MIN(MAX(I11-I15-I19,0),I21) -> 0 | J22: =MIN(MAX(J11-J15-J19,0),J21) -> 0 | ... CT22: =MIN(MAX(CT11-CT15-CT19,0),CT21) -> 0
B23: GP Unreturned - End | C23: =C21-C22 -> 0 | D23: =D21-D22 -> 0 | E23: =E21-E22 -> 0 | F23: =F21-F22 -> 0 | G23: =G21-G22 -> 0 | H23: =H21-H22 -> 0 | I23: =I21-I22 -> 0 | J23: =J21-J22 -> 0 | ... CT23: =CT21-CT22 -> 0
B25: Residual Cash | C25: =MAX(C11-C15-C19-C22,0) -> 0 | D25: =MAX(D11-D15-D19-D22,0) -> 0 | E25: =MAX(E11-E15-E19-E22,0) -> 0 | F25: =MAX(F11-F15-F19-F22,0) -> 0 | G25: =MAX(G11-G15-G19-G22,0) -> 0 | H25: =MAX(H11-H15-H19-H22,0) -> 0 | I25: =MAX(I11-I15-I19-I22,0) -> 0 | J25: =MAX(J11-J15-J19-J22,0) -> 0 | ... CT25: =MAX(CT11-CT15-CT19-CT22,0) -> 0
B26: LP Residual Share | C26: =C25*Inputs!$B$77 -> 0 | D26: =D25*Inputs!$B$77 -> 0 | E26: =E25*Inputs!$B$77 -> 0 | F26: =F25*Inputs!$B$77 -> 0 | G26: =G25*Inputs!$B$77 -> 0 | H26: =H25*Inputs!$B$77 -> 0 | I26: =I25*Inputs!$B$77 -> 0 | J26: =J25*Inputs!$B$77 -> 0 | ... CT26: =CT25*Inputs!$B$77 -> 0
B27: GP Residual Share | C27: =C25*(1-Inputs!$B$77) -> 0 | D27: =D25*(1-Inputs!$B$77) -> 0 | E27: =E25*(1-Inputs!$B$77) -> 0 | F27: =F25*(1-Inputs!$B$77) -> 0 | G27: =G25*(1-Inputs!$B$77) -> 0 | H27: =H25*(1-Inputs!$B$77) -> 0 | I27: =I25*(1-Inputs!$B$77) -> 0 | J27: =J25*(1-Inputs!$B$77) -> 0 | ... CT27: =CT25*(1-Inputs!$B$77) -> 0
B29: LP Net Cash Flow | C29: =-C9+C15+C19+C26 -> -7234888.2 | D29: =-D9+D15+D19+D26 -> -988505.98 | E29: =-E9+E15+E19+E26 -> -1255209.3 | F29: =-F9+F15+F19+F26 -> -1558849 | G29: =-G9+G15+G19+G26 -> -1891085.5 | H29: =-H9+H15+H19+H26 -> -1246458.1 | I29: =-I9+I15+I19+I26 -> 0 | J29: =-J9+J15+J19+J26 -> 0 | ... CT29: =-CT9+CT15+CT19+CT26 -> 0
B30: GP Net Cash Flow | C30: =-C10+C22+C27 -> 0 | D30: =-D10+D22+D27 -> 0 | E30: =-E10+E22+E27 -> 0 | F30: =-F10+F22+F27 -> 0 | G30: =-G10+G22+G27 -> 0 | H30: =-H10+H22+H27 -> 0 | I30: =-I10+I22+I27 -> 0 | J30: =-J10+J22+J27 -> 0 | ... CT30: =-CT10+CT22+CT27 -> 0
B32: LP IRR | C32: =IFERROR(XIRR(C29:CT29,C7:CT7,0.1),"") -> 0.097126354
B33: LP Equity Multiple | C33: =IFERROR(SUMIF(C29:CT29,">0")/-SUMIF(C29:CT29,"<0"),"") -> 1.4688583
B34: LP Total Profit | C34: =SUM(C29:CT29) -> 6646064.4
B35: GP IRR | C35: =IF($C$3<1,"n/a (no GP cash)",IFERROR(XIRR(C30:CT30,C7:CT7,0.1),"")) -> n/a (no GP cash)
B36: GP Equity Multiple | C36: =IF($C$3<1,"n/a (no GP cash)",IFERROR(SUMIF(C30:CT30,">0")/-SUMIF(C30:CT30,"<0"),"")) -> n/a (no GP cash)
B37: GP Total Profit | C37: =SUM(C30:CT30) -> 568687.01

Sheet Summary
A1: PROJECT SUMMARY
A3: Total Units | B3: =Inputs!$B$6 -> 288
A4: Net Rentable SF | B4: =Inputs!$B$5 -> 271710
A5: Total Project Cost | B5: =Inputs!$B$86 -> 62502419
A6: Cost / Unit | B6: =IFERROR(Inputs!$B$86/Inputs!$B$6,0) -> 217022.29
A7: Cost / SF | B7: =IFERROR(Inputs!$B$86/Inputs!$B$5,0) -> 230.03356
A8: Construction Loan (Peak Balance) | B8: =MAX('Monthly CF'!C44:CT44) -> 48702094
A9: Effective LTC | B9: =IFERROR(MAX('Monthly CF'!C44:CT44)/Inputs!$B$86,0) -> 0.77920335
A10: Net Equity Required | B10: =Inputs!$B$87 -> 14174996
A11: Stabilized NOI (Refi Month x 12) | B11: =INDEX('Monthly CF'!$C$26:$CT$26,1,Inputs!$B$58)*12 -> 4132310.1
A12: Development Yield (Stab. NOI / TPC) | B12: =IFERROR(INDEX('Monthly CF'!$C$26:$CT$26,1,Inputs!$B$58)*12/Inputs!$B$86,0) -> 0.066114403
A13: Refi Value | B13: =INDEX('Monthly CF'!$C$46:$CT$46,1,Inputs!$B$58) -> 68871835
A14: Perm Loan Amount | B14: =Inputs!$B$91 -> 49878072
A15: Net Cash-Out at Refi | B15: =INDEX('Monthly CF'!$C$49:$CT$49,1,Inputs!$B$58) -> -115825.74
A16: Going-In DSCR (Perm) | B16: =IFERROR(INDEX('Monthly CF'!$C$26:$CT$26,1,Inputs!$B$58)*12/((Inputs!$B$92+Inputs!$B$91*Inputs!$B$64/12)*12),0) -> 1.135698
A17: Sale Price (if Sell) | B17: =IF(Inputs!$B$69="Sell",INDEX('Monthly CF'!$C$58:$CT$58,1,Inputs!$B$70),0) -> 65794388
A18: Project IRR | B18: ='Monthly CF'!C63 -> 0.10394762
A19: Project Equity Multiple | B19: ='Monthly CF'!C64 -> 1.5089773
A20: Total Profit | B20: ='Monthly CF'!C65 -> 7214751.4
A21: LP IRR | B21: =Waterfall!C32 -> 0.097126354
A22: GP IRR | B22: =Waterfall!C35 -> n/a (no GP cash)

Sheet Stoa Benchmarks
A1: STOA-ERA MODEL: EXACT SETTINGS PRESERVED / CHANGED
A3: PRESERVED EXACTLY (same equations/defaults):
A4: Comp-driven rents: rent = weighted comp average by unit type x (1 - delta). Deltas were -4% (1BR), -5% (2BR), +12% (3BR) on Inverness.
A5: Vacancy 7%; rent growth 2%; lease-up 14 months; phased delivery (lease-up starts before completion).
A6: Expense phase-in: each line starts N months before lease-up; cost = full x (%fixed + (1-%fixed) x occupancy). Their %fixed: Payroll 100%, G&A 100%, Marketing 250% (capped at 100% here), R&M 20%, Utilities 50%, Insurance 100%.
A7: Contingencies 10% hard / 2% soft; GC overhead 5% grossed up; GC profit 4%; developer fee 3.5% + 0.5%; impact fees $4,127/unit.
A8: Soft cost unit rates: architectural $1,800/u; landscape $150/u; geotech $20k; civil $95k; Phase 1 $2.5k; title $68k; attorney $5.1k; appraisal $4.5k; other closing $700; NGBS $230/u; consulting $200/u; GL insurance hard/1000 x 3.
A9: Bell-curve draws: SD 6 hard / SD 10 soft; construction loan LTC 75%, WSJ Prime + 0.50%; equity draws first, then debt; interest capitalized.
A10: Perm refi: value = stabilized NOI x 12 / valuation cap; LTV 75%; 420-mo amortization; MIP 0.25%; cash-out at refi. Their refi month: 33. Their caps: 5.5% valuation / 6.5% exit. Cost of sale 0.75%.
A11: Waterfall: 8% pref first. (Their hurdles 10%/12% with 10/20/30 promote simplified here to pref -> return of capital -> residual split; extendable on request.)
A12: GC profit + dev fee taken as GP in-kind equity: preserved as a toggle (Inputs B78). Stoa: On. You (not self-building): Off.
A14: CHANGED AND WHY:
... A24: Marketing %fixed of 250% capped at 100% (their value scaled marketing ABOVE full budget during lease-up; if you want that behavior, set %fixed above 100%).

Sheet Checks
A1: Check | B1: Status
A2: Construction draws sum = budget | B2: ='Construction Budget'!C35 -> OK
A3: Effective LTC between 65% and 85% (loan carries capitalized interest, like Stoa) | B3: =IF(AND(MAX('Monthly CF'!C44:CT44)/Inputs!$B$86>=0.65,MAX('Monthly CF'!C44:CT44)/Inputs!$B$86<=0.85),"OK","CHECK") -> OK
A4: Equity fully drawn before debt (equity remaining at first loan draw = 0) | B4: =IF(SUMPRODUCT(('Monthly CF'!C41:CT41>0)*('Monthly CF'!C39:CT39))<1,"OK","ERROR") -> OK
A5: Refi month after stabilization | B5: =IF(Inputs!$B$58>=Inputs!$B$13,"OK","CHECK") -> OK
A6: Sale month after refi (if Sell) | B6: =IF(OR(Inputs!$B$69<>"Sell",Inputs!$B$70>Inputs!$B$58),"OK","ERROR") -> OK
A7: Waterfall distributions = project distributions | B7: =IF(ABS(SUMIF(Waterfall!C29:CT29,">0")+SUMIF(Waterfall!C30:CT30,">0")-SUM(Waterfall!C11:CT11))<1,"OK","ERROR") -> OK
A8: Waterfall contributions = equity drawn | B8: =IF(ABS(SUM(Waterfall!C8:CT8)-SUM('Monthly CF'!C38:CT38))<1,"OK","ERROR") -> OK
